[2022-07-17 22:19:04,584] {taskinstance.py:1179} INFO - Dependencies all met for <TaskInstance: bitcoin.get_api manual__2022-07-17T22:19:02.012885+00:00 [queued]>
[2022-07-17 22:19:04,612] {taskinstance.py:1179} INFO - Dependencies all met for <TaskInstance: bitcoin.get_api manual__2022-07-17T22:19:02.012885+00:00 [queued]>
[2022-07-17 22:19:04,613] {taskinstance.py:1376} INFO - 
--------------------------------------------------------------------------------
[2022-07-17 22:19:04,613] {taskinstance.py:1377} INFO - Starting attempt 1 of 1
[2022-07-17 22:19:04,613] {taskinstance.py:1378} INFO - 
--------------------------------------------------------------------------------
[2022-07-17 22:19:04,804] {taskinstance.py:1397} INFO - Executing <Task(PythonOperator): get_api> on 2022-07-17 22:19:02.012885+00:00
[2022-07-17 22:19:04,809] {standard_task_runner.py:52} INFO - Started process 1362 to run task
[2022-07-17 22:19:04,816] {standard_task_runner.py:79} INFO - Running: ['***', 'tasks', 'run', 'bitcoin', 'get_api', 'manual__2022-07-17T22:19:02.012885+00:00', '--job-id', '169', '--raw', '--subdir', 'DAGS_FOLDER/projeto_api.py', '--cfg-path', '/tmp/tmp148y_hul', '--error-file', '/tmp/tmpyf5wz_0i']
[2022-07-17 22:19:04,816] {standard_task_runner.py:80} INFO - Job 169: Subtask get_api
[2022-07-17 22:19:05,133] {task_command.py:371} INFO - Running <TaskInstance: bitcoin.get_api manual__2022-07-17T22:19:02.012885+00:00 [running]> on host 35b853283dd2
[2022-07-17 22:19:05,506] {taskinstance.py:1591} INFO - Exporting the following env vars:
AIRFLOW_CTX_DAG_OWNER=***
AIRFLOW_CTX_DAG_ID=bitcoin
AIRFLOW_CTX_TASK_ID=get_api
AIRFLOW_CTX_EXECUTION_DATE=2022-07-17T22:19:02.012885+00:00
AIRFLOW_CTX_TRY_NUMBER=1
AIRFLOW_CTX_DAG_RUN_ID=manual__2022-07-17T22:19:02.012885+00:00
[2022-07-17 22:19:06,646] {taskinstance.py:1909} ERROR - Task failed with exception
Traceback (most recent call last):
  File "/home/airflow/.local/lib/python3.7/site-packages/airflow/operators/python.py", line 171, in execute
    return_value = self.execute_callable()
  File "/home/airflow/.local/lib/python3.7/site-packages/airflow/operators/python.py", line 189, in execute_callable
    return self.python_callable(*self.op_args, **self.op_kwargs)
  File "/opt/airflow/dags/functions/dag_functions.py", line 21, in getAndInputDaySummary
    password="airflow", port="5434", schema='public')
  File "/opt/airflow/dags/functions/db_manipulation.py", line 17, in __init__
    database=db, host=host, port=port, password=password, user=user)
  File "/home/airflow/.local/lib/python3.7/site-packages/psycopg2/__init__.py", line 122, in connect
    conn = _connect(dsn, connection_factory=connection_factory, **kwasync)
psycopg2.OperationalError: connection to server at "localhost" (127.0.0.1), port 5434 failed: Connection refused
	Is the server running on that host and accepting TCP/IP connections?
connection to server at "localhost" (::1), port 5434 failed: Cannot assign requested address
	Is the server running on that host and accepting TCP/IP connections?

[2022-07-17 22:19:06,661] {taskinstance.py:1420} INFO - Marking task as FAILED. dag_id=bitcoin, task_id=get_api, execution_date=20220717T221902, start_date=20220717T221904, end_date=20220717T221906
[2022-07-17 22:19:06,706] {standard_task_runner.py:97} ERROR - Failed to execute job 169 for task get_api (connection to server at "localhost" (127.0.0.1), port 5434 failed: Connection refused
	Is the server running on that host and accepting TCP/IP connections?
connection to server at "localhost" (::1), port 5434 failed: Cannot assign requested address
	Is the server running on that host and accepting TCP/IP connections?
; 1362)
[2022-07-17 22:19:06,732] {local_task_job.py:156} INFO - Task exited with return code 1
[2022-07-17 22:19:06,873] {local_task_job.py:273} INFO - 0 downstream tasks scheduled from follow-on schedule check
