[2022-07-17 22:11:44,878] {taskinstance.py:1179} INFO - Dependencies all met for <TaskInstance: bitcoin.get_api manual__2022-07-17T22:11:42.552246+00:00 [queued]>
[2022-07-17 22:11:44,913] {taskinstance.py:1179} INFO - Dependencies all met for <TaskInstance: bitcoin.get_api manual__2022-07-17T22:11:42.552246+00:00 [queued]>
[2022-07-17 22:11:44,914] {taskinstance.py:1376} INFO - 
--------------------------------------------------------------------------------
[2022-07-17 22:11:44,914] {taskinstance.py:1377} INFO - Starting attempt 1 of 1
[2022-07-17 22:11:44,914] {taskinstance.py:1378} INFO - 
--------------------------------------------------------------------------------
[2022-07-17 22:11:45,015] {taskinstance.py:1397} INFO - Executing <Task(PythonOperator): get_api> on 2022-07-17 22:11:42.552246+00:00
[2022-07-17 22:11:45,021] {standard_task_runner.py:52} INFO - Started process 1060 to run task
[2022-07-17 22:11:45,034] {standard_task_runner.py:79} INFO - Running: ['***', 'tasks', 'run', 'bitcoin', 'get_api', 'manual__2022-07-17T22:11:42.552246+00:00', '--job-id', '167', '--raw', '--subdir', 'DAGS_FOLDER/projeto_api.py', '--cfg-path', '/tmp/tmp9hspgc6h', '--error-file', '/tmp/tmpsg_zkzy_']
[2022-07-17 22:11:45,034] {standard_task_runner.py:80} INFO - Job 167: Subtask get_api
[2022-07-17 22:11:45,262] {task_command.py:371} INFO - Running <TaskInstance: bitcoin.get_api manual__2022-07-17T22:11:42.552246+00:00 [running]> on host 35b853283dd2
[2022-07-17 22:11:45,741] {taskinstance.py:1591} INFO - Exporting the following env vars:
AIRFLOW_CTX_DAG_OWNER=***
AIRFLOW_CTX_DAG_ID=bitcoin
AIRFLOW_CTX_TASK_ID=get_api
AIRFLOW_CTX_EXECUTION_DATE=2022-07-17T22:11:42.552246+00:00
AIRFLOW_CTX_TRY_NUMBER=1
AIRFLOW_CTX_DAG_RUN_ID=manual__2022-07-17T22:11:42.552246+00:00
[2022-07-17 22:11:46,491] {taskinstance.py:1909} ERROR - Task failed with exception
Traceback (most recent call last):
  File "/home/airflow/.local/lib/python3.7/site-packages/airflow/operators/python.py", line 171, in execute
    return_value = self.execute_callable()
  File "/home/airflow/.local/lib/python3.7/site-packages/airflow/operators/python.py", line 189, in execute_callable
    return self.python_callable(*self.op_args, **self.op_kwargs)
  File "/opt/airflow/dags/functions/dag_functions.py", line 21, in getAndInputDaySummary
    password="airflow", port="5434", schema='public')
  File "/opt/airflow/dags/functions/db_manipulation.py", line 17, in __init__
    database=db, host=host, port=port, password=password, user=user)
  File "/home/airflow/.local/lib/python3.7/site-packages/psycopg2/__init__.py", line 122, in connect
    conn = _connect(dsn, connection_factory=connection_factory, **kwasync)
psycopg2.OperationalError: connection to server at "localhost" (127.0.0.1), port 5434 failed: Connection refused
	Is the server running on that host and accepting TCP/IP connections?
connection to server at "localhost" (::1), port 5434 failed: Cannot assign requested address
	Is the server running on that host and accepting TCP/IP connections?

[2022-07-17 22:11:46,536] {taskinstance.py:1420} INFO - Marking task as FAILED. dag_id=bitcoin, task_id=get_api, execution_date=20220717T221142, start_date=20220717T221144, end_date=20220717T221146
[2022-07-17 22:11:46,585] {standard_task_runner.py:97} ERROR - Failed to execute job 167 for task get_api (connection to server at "localhost" (127.0.0.1), port 5434 failed: Connection refused
	Is the server running on that host and accepting TCP/IP connections?
connection to server at "localhost" (::1), port 5434 failed: Cannot assign requested address
	Is the server running on that host and accepting TCP/IP connections?
; 1060)
[2022-07-17 22:11:46,629] {local_task_job.py:156} INFO - Task exited with return code 1
[2022-07-17 22:11:46,681] {local_task_job.py:273} INFO - 0 downstream tasks scheduled from follow-on schedule check
