[2022-07-07 01:05:29,078] {processor.py:153} INFO - Started process (PID=70) to work on /opt/airflow/dags/projeto_api.py
[2022-07-07 01:05:29,287] {processor.py:641} INFO - Processing file /opt/airflow/dags/projeto_api.py for tasks to queue
[2022-07-07 01:05:29,288] {logging_mixin.py:115} INFO - [2022-07-07 01:05:29,288] {dagbag.py:507} INFO - Filling up the DagBag from /opt/airflow/dags/projeto_api.py
[2022-07-07 01:05:31,232] {logging_mixin.py:115} INFO - [2022-07-07 01:05:31,219] {dagbag.py:320} ERROR - Failed to import: /opt/airflow/dags/projeto_api.py
Traceback (most recent call last):
  File "/home/airflow/.local/lib/python3.7/site-packages/airflow/models/dagbag.py", line 317, in parse
    loader.exec_module(new_module)
  File "<frozen importlib._bootstrap_external>", line 728, in exec_module
  File "<frozen importlib._bootstrap>", line 219, in _call_with_frames_removed
  File "/opt/airflow/dags/projeto_api.py", line 27, in <module>
    load_json = Api_conn.load_data_json(dia1)
  File "/opt/airflow/dags/projeto_api.py", line 23, in load_data_json
    return json.loads(data)
  File "/usr/local/lib/python3.7/json/__init__.py", line 341, in loads
    raise TypeError(f'the JSON object must be str, bytes or bytearray, '
TypeError: the JSON object must be str, bytes or bytearray, not Response
[2022-07-07 01:05:31,232] {processor.py:653} WARNING - No viable dags retrieved from /opt/airflow/dags/projeto_api.py
[2022-07-07 01:05:31,298] {processor.py:161} INFO - Processing /opt/airflow/dags/projeto_api.py took 2.225 seconds
[2022-07-07 01:06:01,377] {processor.py:153} INFO - Started process (PID=97) to work on /opt/airflow/dags/projeto_api.py
[2022-07-07 01:06:01,509] {processor.py:641} INFO - Processing file /opt/airflow/dags/projeto_api.py for tasks to queue
[2022-07-07 01:06:01,677] {logging_mixin.py:115} INFO - [2022-07-07 01:06:01,677] {dagbag.py:507} INFO - Filling up the DagBag from /opt/airflow/dags/projeto_api.py
[2022-07-07 01:06:01,954] {logging_mixin.py:115} INFO - [2022-07-07 01:06:01,948] {dagbag.py:320} ERROR - Failed to import: /opt/airflow/dags/projeto_api.py
Traceback (most recent call last):
  File "/home/airflow/.local/lib/python3.7/site-packages/airflow/models/dagbag.py", line 317, in parse
    loader.exec_module(new_module)
  File "<frozen importlib._bootstrap_external>", line 728, in exec_module
  File "<frozen importlib._bootstrap>", line 219, in _call_with_frames_removed
  File "/opt/airflow/dags/projeto_api.py", line 27, in <module>
    load_json = Api_conn.load_data_json(dia1)
  File "/opt/airflow/dags/projeto_api.py", line 23, in load_data_json
    return json.loads(data)
  File "/usr/local/lib/python3.7/json/__init__.py", line 341, in loads
    raise TypeError(f'the JSON object must be str, bytes or bytearray, '
TypeError: the JSON object must be str, bytes or bytearray, not Response
[2022-07-07 01:06:01,954] {processor.py:653} WARNING - No viable dags retrieved from /opt/airflow/dags/projeto_api.py
[2022-07-07 01:06:02,230] {processor.py:161} INFO - Processing /opt/airflow/dags/projeto_api.py took 0.858 seconds
[2022-07-07 01:06:32,307] {processor.py:153} INFO - Started process (PID=115) to work on /opt/airflow/dags/projeto_api.py
[2022-07-07 01:06:32,308] {processor.py:641} INFO - Processing file /opt/airflow/dags/projeto_api.py for tasks to queue
[2022-07-07 01:06:32,308] {logging_mixin.py:115} INFO - [2022-07-07 01:06:32,308] {dagbag.py:507} INFO - Filling up the DagBag from /opt/airflow/dags/projeto_api.py
[2022-07-07 01:06:32,534] {logging_mixin.py:115} INFO - [2022-07-07 01:06:32,529] {dagbag.py:320} ERROR - Failed to import: /opt/airflow/dags/projeto_api.py
Traceback (most recent call last):
  File "/home/airflow/.local/lib/python3.7/site-packages/airflow/models/dagbag.py", line 317, in parse
    loader.exec_module(new_module)
  File "<frozen importlib._bootstrap_external>", line 728, in exec_module
  File "<frozen importlib._bootstrap>", line 219, in _call_with_frames_removed
  File "/opt/airflow/dags/projeto_api.py", line 27, in <module>
    load_json = Api_conn.load_data_json(dia1)
  File "/opt/airflow/dags/projeto_api.py", line 23, in load_data_json
    return json.loads(data)
  File "/usr/local/lib/python3.7/json/__init__.py", line 341, in loads
    raise TypeError(f'the JSON object must be str, bytes or bytearray, '
TypeError: the JSON object must be str, bytes or bytearray, not Response
[2022-07-07 01:06:32,535] {processor.py:653} WARNING - No viable dags retrieved from /opt/airflow/dags/projeto_api.py
[2022-07-07 01:06:32,664] {processor.py:161} INFO - Processing /opt/airflow/dags/projeto_api.py took 0.362 seconds
[2022-07-07 01:07:02,758] {processor.py:153} INFO - Started process (PID=142) to work on /opt/airflow/dags/projeto_api.py
[2022-07-07 01:07:02,925] {processor.py:641} INFO - Processing file /opt/airflow/dags/projeto_api.py for tasks to queue
[2022-07-07 01:07:02,926] {logging_mixin.py:115} INFO - [2022-07-07 01:07:02,926] {dagbag.py:507} INFO - Filling up the DagBag from /opt/airflow/dags/projeto_api.py
[2022-07-07 01:07:03,255] {logging_mixin.py:115} INFO - [2022-07-07 01:07:03,254] {dagbag.py:320} ERROR - Failed to import: /opt/airflow/dags/projeto_api.py
Traceback (most recent call last):
  File "/home/airflow/.local/lib/python3.7/site-packages/airflow/models/dagbag.py", line 317, in parse
    loader.exec_module(new_module)
  File "<frozen importlib._bootstrap_external>", line 728, in exec_module
  File "<frozen importlib._bootstrap>", line 219, in _call_with_frames_removed
  File "/opt/airflow/dags/projeto_api.py", line 27, in <module>
    load_json = Api_conn.load_data_json(dia1)
  File "/opt/airflow/dags/projeto_api.py", line 23, in load_data_json
    return json.loads(data)
  File "/usr/local/lib/python3.7/json/__init__.py", line 341, in loads
    raise TypeError(f'the JSON object must be str, bytes or bytearray, '
TypeError: the JSON object must be str, bytes or bytearray, not Response
[2022-07-07 01:07:03,320] {processor.py:653} WARNING - No viable dags retrieved from /opt/airflow/dags/projeto_api.py
[2022-07-07 01:07:03,479] {processor.py:161} INFO - Processing /opt/airflow/dags/projeto_api.py took 0.725 seconds
[2022-07-07 01:07:34,403] {processor.py:153} INFO - Started process (PID=153) to work on /opt/airflow/dags/projeto_api.py
[2022-07-07 01:07:34,696] {processor.py:641} INFO - Processing file /opt/airflow/dags/projeto_api.py for tasks to queue
[2022-07-07 01:07:34,697] {logging_mixin.py:115} INFO - [2022-07-07 01:07:34,697] {dagbag.py:507} INFO - Filling up the DagBag from /opt/airflow/dags/projeto_api.py
[2022-07-07 01:07:49,948] {logging_mixin.py:115} INFO - [2022-07-07 01:07:49,854] {dagbag.py:320} ERROR - Failed to import: /opt/airflow/dags/projeto_api.py
Traceback (most recent call last):
  File "/home/airflow/.local/lib/python3.7/site-packages/urllib3/connection.py", line 175, in _new_conn
    (self._dns_host, self.port), self.timeout, **extra_kw
  File "/home/airflow/.local/lib/python3.7/site-packages/urllib3/util/connection.py", line 72, in create_connection
    for res in socket.getaddrinfo(host, port, family, socket.SOCK_STREAM):
  File "/usr/local/lib/python3.7/socket.py", line 752, in getaddrinfo
    for res in _socket.getaddrinfo(host, port, family, type, proto, flags):
socket.gaierror: [Errno -3] Temporary failure in name resolution

During handling of the above exception, another exception occurred:

Traceback (most recent call last):
  File "/home/airflow/.local/lib/python3.7/site-packages/urllib3/connectionpool.py", line 710, in urlopen
    chunked=chunked,
  File "/home/airflow/.local/lib/python3.7/site-packages/urllib3/connectionpool.py", line 386, in _make_request
    self._validate_conn(conn)
  File "/home/airflow/.local/lib/python3.7/site-packages/urllib3/connectionpool.py", line 1040, in _validate_conn
    conn.connect()
  File "/home/airflow/.local/lib/python3.7/site-packages/urllib3/connection.py", line 358, in connect
    self.sock = conn = self._new_conn()
  File "/home/airflow/.local/lib/python3.7/site-packages/urllib3/connection.py", line 187, in _new_conn
    self, "Failed to establish a new connection: %s" % e
urllib3.exceptions.NewConnectionError: <urllib3.connection.HTTPSConnection object at 0x7f3e6d1fdc50>: Failed to establish a new connection: [Errno -3] Temporary failure in name resolution

During handling of the above exception, another exception occurred:

Traceback (most recent call last):
  File "/home/airflow/.local/lib/python3.7/site-packages/requests/adapters.py", line 450, in send
    timeout=timeout
  File "/home/airflow/.local/lib/python3.7/site-packages/urllib3/connectionpool.py", line 786, in urlopen
    method, url, error=e, _pool=self, _stacktrace=sys.exc_info()[2]
  File "/home/airflow/.local/lib/python3.7/site-packages/urllib3/util/retry.py", line 592, in increment
    raise MaxRetryError(_pool, url, error or ResponseError(cause))
urllib3.exceptions.MaxRetryError: HTTPSConnectionPool(host='www.mercadobitcoin.net', port=443): Max retries exceeded with url: /api/BTC/day-summary/2022/5/2/ (Caused by NewConnectionError('<urllib3.connection.HTTPSConnection object at 0x7f3e6d1fdc50>: Failed to establish a new connection: [Errno -3] Temporary failure in name resolution'))

During handling of the above exception, another exception occurred:

Traceback (most recent call last):
  File "/home/airflow/.local/lib/python3.7/site-packages/airflow/models/dagbag.py", line 317, in parse
    loader.exec_module(new_module)
  File "<frozen importlib._bootstrap_external>", line 728, in exec_module
  File "<frozen importlib._bootstrap>", line 219, in _call_with_frames_removed
  File "/opt/airflow/dags/projeto_api.py", line 26, in <module>
    dia1 = Api_conn.get_api(2, 5, 2022)
  File "/opt/airflow/dags/projeto_api.py", line 19, in get_api
    response_API = requests.get(f'https://www.mercadobitcoin.net/api/BTC/day-summary/{year}/{month}/{day}/')
  File "/home/airflow/.local/lib/python3.7/site-packages/requests/api.py", line 75, in get
    return request('get', url, params=params, **kwargs)
  File "/home/airflow/.local/lib/python3.7/site-packages/requests/api.py", line 61, in request
    return session.request(method=method, url=url, **kwargs)
  File "/home/airflow/.local/lib/python3.7/site-packages/requests/sessions.py", line 529, in request
    resp = self.send(prep, **send_kwargs)
  File "/home/airflow/.local/lib/python3.7/site-packages/requests/sessions.py", line 645, in send
    r = adapter.send(request, **kwargs)
  File "/home/airflow/.local/lib/python3.7/site-packages/requests/adapters.py", line 519, in send
    raise ConnectionError(e, request=request)
requests.exceptions.ConnectionError: HTTPSConnectionPool(host='www.mercadobitcoin.net', port=443): Max retries exceeded with url: /api/BTC/day-summary/2022/5/2/ (Caused by NewConnectionError('<urllib3.connection.HTTPSConnection object at 0x7f3e6d1fdc50>: Failed to establish a new connection: [Errno -3] Temporary failure in name resolution'))
[2022-07-07 01:07:49,949] {processor.py:653} WARNING - No viable dags retrieved from /opt/airflow/dags/projeto_api.py
[2022-07-07 01:07:50,040] {processor.py:161} INFO - Processing /opt/airflow/dags/projeto_api.py took 15.839 seconds
[2022-07-07 01:08:20,141] {processor.py:153} INFO - Started process (PID=190) to work on /opt/airflow/dags/projeto_api.py
[2022-07-07 01:08:20,185] {processor.py:641} INFO - Processing file /opt/airflow/dags/projeto_api.py for tasks to queue
[2022-07-07 01:08:20,186] {logging_mixin.py:115} INFO - [2022-07-07 01:08:20,186] {dagbag.py:507} INFO - Filling up the DagBag from /opt/airflow/dags/projeto_api.py
[2022-07-07 01:08:25,642] {logging_mixin.py:115} INFO - [2022-07-07 01:08:25,638] {dagbag.py:320} ERROR - Failed to import: /opt/airflow/dags/projeto_api.py
Traceback (most recent call last):
  File "/home/airflow/.local/lib/python3.7/site-packages/urllib3/connection.py", line 175, in _new_conn
    (self._dns_host, self.port), self.timeout, **extra_kw
  File "/home/airflow/.local/lib/python3.7/site-packages/urllib3/util/connection.py", line 72, in create_connection
    for res in socket.getaddrinfo(host, port, family, socket.SOCK_STREAM):
  File "/usr/local/lib/python3.7/socket.py", line 752, in getaddrinfo
    for res in _socket.getaddrinfo(host, port, family, type, proto, flags):
socket.gaierror: [Errno -3] Temporary failure in name resolution

During handling of the above exception, another exception occurred:

Traceback (most recent call last):
  File "/home/airflow/.local/lib/python3.7/site-packages/urllib3/connectionpool.py", line 710, in urlopen
    chunked=chunked,
  File "/home/airflow/.local/lib/python3.7/site-packages/urllib3/connectionpool.py", line 386, in _make_request
    self._validate_conn(conn)
  File "/home/airflow/.local/lib/python3.7/site-packages/urllib3/connectionpool.py", line 1040, in _validate_conn
    conn.connect()
  File "/home/airflow/.local/lib/python3.7/site-packages/urllib3/connection.py", line 358, in connect
    self.sock = conn = self._new_conn()
  File "/home/airflow/.local/lib/python3.7/site-packages/urllib3/connection.py", line 187, in _new_conn
    self, "Failed to establish a new connection: %s" % e
urllib3.exceptions.NewConnectionError: <urllib3.connection.HTTPSConnection object at 0x7f3e6d1fdc10>: Failed to establish a new connection: [Errno -3] Temporary failure in name resolution

During handling of the above exception, another exception occurred:

Traceback (most recent call last):
  File "/home/airflow/.local/lib/python3.7/site-packages/requests/adapters.py", line 450, in send
    timeout=timeout
  File "/home/airflow/.local/lib/python3.7/site-packages/urllib3/connectionpool.py", line 786, in urlopen
    method, url, error=e, _pool=self, _stacktrace=sys.exc_info()[2]
  File "/home/airflow/.local/lib/python3.7/site-packages/urllib3/util/retry.py", line 592, in increment
    raise MaxRetryError(_pool, url, error or ResponseError(cause))
urllib3.exceptions.MaxRetryError: HTTPSConnectionPool(host='www.mercadobitcoin.net', port=443): Max retries exceeded with url: /api/BTC/day-summary/2022/5/2/ (Caused by NewConnectionError('<urllib3.connection.HTTPSConnection object at 0x7f3e6d1fdc10>: Failed to establish a new connection: [Errno -3] Temporary failure in name resolution'))

During handling of the above exception, another exception occurred:

Traceback (most recent call last):
  File "/home/airflow/.local/lib/python3.7/site-packages/airflow/models/dagbag.py", line 317, in parse
    loader.exec_module(new_module)
  File "<frozen importlib._bootstrap_external>", line 728, in exec_module
  File "<frozen importlib._bootstrap>", line 219, in _call_with_frames_removed
  File "/opt/airflow/dags/projeto_api.py", line 26, in <module>
    dia1 = Api_conn.get_api(2, 5, 2022)
  File "/opt/airflow/dags/projeto_api.py", line 19, in get_api
    response_API = requests.get(f'https://www.mercadobitcoin.net/api/BTC/day-summary/{year}/{month}/{day}/')
  File "/home/airflow/.local/lib/python3.7/site-packages/requests/api.py", line 75, in get
    return request('get', url, params=params, **kwargs)
  File "/home/airflow/.local/lib/python3.7/site-packages/requests/api.py", line 61, in request
    return session.request(method=method, url=url, **kwargs)
  File "/home/airflow/.local/lib/python3.7/site-packages/requests/sessions.py", line 529, in request
    resp = self.send(prep, **send_kwargs)
  File "/home/airflow/.local/lib/python3.7/site-packages/requests/sessions.py", line 645, in send
    r = adapter.send(request, **kwargs)
  File "/home/airflow/.local/lib/python3.7/site-packages/requests/adapters.py", line 519, in send
    raise ConnectionError(e, request=request)
requests.exceptions.ConnectionError: HTTPSConnectionPool(host='www.mercadobitcoin.net', port=443): Max retries exceeded with url: /api/BTC/day-summary/2022/5/2/ (Caused by NewConnectionError('<urllib3.connection.HTTPSConnection object at 0x7f3e6d1fdc10>: Failed to establish a new connection: [Errno -3] Temporary failure in name resolution'))
[2022-07-07 01:08:25,643] {processor.py:653} WARNING - No viable dags retrieved from /opt/airflow/dags/projeto_api.py
[2022-07-07 01:08:25,747] {processor.py:161} INFO - Processing /opt/airflow/dags/projeto_api.py took 5.609 seconds
[2022-07-07 01:08:55,822] {processor.py:153} INFO - Started process (PID=219) to work on /opt/airflow/dags/projeto_api.py
[2022-07-07 01:08:55,887] {processor.py:641} INFO - Processing file /opt/airflow/dags/projeto_api.py for tasks to queue
[2022-07-07 01:08:55,888] {logging_mixin.py:115} INFO - [2022-07-07 01:08:55,888] {dagbag.py:507} INFO - Filling up the DagBag from /opt/airflow/dags/projeto_api.py
[2022-07-07 01:08:59,430] {logging_mixin.py:115} INFO - [2022-07-07 01:08:59,426] {dagbag.py:320} ERROR - Failed to import: /opt/airflow/dags/projeto_api.py
Traceback (most recent call last):
  File "/home/airflow/.local/lib/python3.7/site-packages/urllib3/connection.py", line 175, in _new_conn
    (self._dns_host, self.port), self.timeout, **extra_kw
  File "/home/airflow/.local/lib/python3.7/site-packages/urllib3/util/connection.py", line 72, in create_connection
    for res in socket.getaddrinfo(host, port, family, socket.SOCK_STREAM):
  File "/usr/local/lib/python3.7/socket.py", line 752, in getaddrinfo
    for res in _socket.getaddrinfo(host, port, family, type, proto, flags):
socket.gaierror: [Errno -3] Temporary failure in name resolution

During handling of the above exception, another exception occurred:

Traceback (most recent call last):
  File "/home/airflow/.local/lib/python3.7/site-packages/urllib3/connectionpool.py", line 710, in urlopen
    chunked=chunked,
  File "/home/airflow/.local/lib/python3.7/site-packages/urllib3/connectionpool.py", line 386, in _make_request
    self._validate_conn(conn)
  File "/home/airflow/.local/lib/python3.7/site-packages/urllib3/connectionpool.py", line 1040, in _validate_conn
    conn.connect()
  File "/home/airflow/.local/lib/python3.7/site-packages/urllib3/connection.py", line 358, in connect
    self.sock = conn = self._new_conn()
  File "/home/airflow/.local/lib/python3.7/site-packages/urllib3/connection.py", line 187, in _new_conn
    self, "Failed to establish a new connection: %s" % e
urllib3.exceptions.NewConnectionError: <urllib3.connection.HTTPSConnection object at 0x7f3e6d1fdc10>: Failed to establish a new connection: [Errno -3] Temporary failure in name resolution

During handling of the above exception, another exception occurred:

Traceback (most recent call last):
  File "/home/airflow/.local/lib/python3.7/site-packages/requests/adapters.py", line 450, in send
    timeout=timeout
  File "/home/airflow/.local/lib/python3.7/site-packages/urllib3/connectionpool.py", line 786, in urlopen
    method, url, error=e, _pool=self, _stacktrace=sys.exc_info()[2]
  File "/home/airflow/.local/lib/python3.7/site-packages/urllib3/util/retry.py", line 592, in increment
    raise MaxRetryError(_pool, url, error or ResponseError(cause))
urllib3.exceptions.MaxRetryError: HTTPSConnectionPool(host='www.mercadobitcoin.net', port=443): Max retries exceeded with url: /api/BTC/day-summary/2022/5/2/ (Caused by NewConnectionError('<urllib3.connection.HTTPSConnection object at 0x7f3e6d1fdc10>: Failed to establish a new connection: [Errno -3] Temporary failure in name resolution'))

During handling of the above exception, another exception occurred:

Traceback (most recent call last):
  File "/home/airflow/.local/lib/python3.7/site-packages/airflow/models/dagbag.py", line 317, in parse
    loader.exec_module(new_module)
  File "<frozen importlib._bootstrap_external>", line 728, in exec_module
  File "<frozen importlib._bootstrap>", line 219, in _call_with_frames_removed
  File "/opt/airflow/dags/projeto_api.py", line 26, in <module>
    dia1 = Api_conn.get_api(2, 5, 2022)
  File "/opt/airflow/dags/projeto_api.py", line 19, in get_api
    response_API = requests.get(f'https://www.mercadobitcoin.net/api/BTC/day-summary/{year}/{month}/{day}/')
  File "/home/airflow/.local/lib/python3.7/site-packages/requests/api.py", line 75, in get
    return request('get', url, params=params, **kwargs)
  File "/home/airflow/.local/lib/python3.7/site-packages/requests/api.py", line 61, in request
    return session.request(method=method, url=url, **kwargs)
  File "/home/airflow/.local/lib/python3.7/site-packages/requests/sessions.py", line 529, in request
    resp = self.send(prep, **send_kwargs)
  File "/home/airflow/.local/lib/python3.7/site-packages/requests/sessions.py", line 645, in send
    r = adapter.send(request, **kwargs)
  File "/home/airflow/.local/lib/python3.7/site-packages/requests/adapters.py", line 519, in send
    raise ConnectionError(e, request=request)
requests.exceptions.ConnectionError: HTTPSConnectionPool(host='www.mercadobitcoin.net', port=443): Max retries exceeded with url: /api/BTC/day-summary/2022/5/2/ (Caused by NewConnectionError('<urllib3.connection.HTTPSConnection object at 0x7f3e6d1fdc10>: Failed to establish a new connection: [Errno -3] Temporary failure in name resolution'))
[2022-07-07 01:08:59,431] {processor.py:653} WARNING - No viable dags retrieved from /opt/airflow/dags/projeto_api.py
[2022-07-07 01:08:59,602] {processor.py:161} INFO - Processing /opt/airflow/dags/projeto_api.py took 3.784 seconds
[2022-07-07 01:09:29,808] {processor.py:153} INFO - Started process (PID=238) to work on /opt/airflow/dags/projeto_api.py
[2022-07-07 01:09:29,855] {processor.py:641} INFO - Processing file /opt/airflow/dags/projeto_api.py for tasks to queue
[2022-07-07 01:09:29,856] {logging_mixin.py:115} INFO - [2022-07-07 01:09:29,856] {dagbag.py:507} INFO - Filling up the DagBag from /opt/airflow/dags/projeto_api.py
[2022-07-07 01:09:39,431] {logging_mixin.py:115} INFO - [2022-07-07 01:09:39,424] {dagbag.py:320} ERROR - Failed to import: /opt/airflow/dags/projeto_api.py
Traceback (most recent call last):
  File "/home/airflow/.local/lib/python3.7/site-packages/urllib3/connection.py", line 175, in _new_conn
    (self._dns_host, self.port), self.timeout, **extra_kw
  File "/home/airflow/.local/lib/python3.7/site-packages/urllib3/util/connection.py", line 72, in create_connection
    for res in socket.getaddrinfo(host, port, family, socket.SOCK_STREAM):
  File "/usr/local/lib/python3.7/socket.py", line 752, in getaddrinfo
    for res in _socket.getaddrinfo(host, port, family, type, proto, flags):
socket.gaierror: [Errno -3] Temporary failure in name resolution

During handling of the above exception, another exception occurred:

Traceback (most recent call last):
  File "/home/airflow/.local/lib/python3.7/site-packages/urllib3/connectionpool.py", line 710, in urlopen
    chunked=chunked,
  File "/home/airflow/.local/lib/python3.7/site-packages/urllib3/connectionpool.py", line 386, in _make_request
    self._validate_conn(conn)
  File "/home/airflow/.local/lib/python3.7/site-packages/urllib3/connectionpool.py", line 1040, in _validate_conn
    conn.connect()
  File "/home/airflow/.local/lib/python3.7/site-packages/urllib3/connection.py", line 358, in connect
    self.sock = conn = self._new_conn()
  File "/home/airflow/.local/lib/python3.7/site-packages/urllib3/connection.py", line 187, in _new_conn
    self, "Failed to establish a new connection: %s" % e
urllib3.exceptions.NewConnectionError: <urllib3.connection.HTTPSConnection object at 0x7f3e6d1feb90>: Failed to establish a new connection: [Errno -3] Temporary failure in name resolution

During handling of the above exception, another exception occurred:

Traceback (most recent call last):
  File "/home/airflow/.local/lib/python3.7/site-packages/requests/adapters.py", line 450, in send
    timeout=timeout
  File "/home/airflow/.local/lib/python3.7/site-packages/urllib3/connectionpool.py", line 786, in urlopen
    method, url, error=e, _pool=self, _stacktrace=sys.exc_info()[2]
  File "/home/airflow/.local/lib/python3.7/site-packages/urllib3/util/retry.py", line 592, in increment
    raise MaxRetryError(_pool, url, error or ResponseError(cause))
urllib3.exceptions.MaxRetryError: HTTPSConnectionPool(host='www.mercadobitcoin.net', port=443): Max retries exceeded with url: /api/BTC/day-summary/2022/5/2/ (Caused by NewConnectionError('<urllib3.connection.HTTPSConnection object at 0x7f3e6d1feb90>: Failed to establish a new connection: [Errno -3] Temporary failure in name resolution'))

During handling of the above exception, another exception occurred:

Traceback (most recent call last):
  File "/home/airflow/.local/lib/python3.7/site-packages/airflow/models/dagbag.py", line 317, in parse
    loader.exec_module(new_module)
  File "<frozen importlib._bootstrap_external>", line 728, in exec_module
  File "<frozen importlib._bootstrap>", line 219, in _call_with_frames_removed
  File "/opt/airflow/dags/projeto_api.py", line 26, in <module>
    dia1 = Api_conn.get_api(2, 5, 2022)
  File "/opt/airflow/dags/projeto_api.py", line 19, in get_api
    response_API = requests.get(f'https://www.mercadobitcoin.net/api/BTC/day-summary/{year}/{month}/{day}/')
  File "/home/airflow/.local/lib/python3.7/site-packages/requests/api.py", line 75, in get
    return request('get', url, params=params, **kwargs)
  File "/home/airflow/.local/lib/python3.7/site-packages/requests/api.py", line 61, in request
    return session.request(method=method, url=url, **kwargs)
  File "/home/airflow/.local/lib/python3.7/site-packages/requests/sessions.py", line 529, in request
    resp = self.send(prep, **send_kwargs)
  File "/home/airflow/.local/lib/python3.7/site-packages/requests/sessions.py", line 645, in send
    r = adapter.send(request, **kwargs)
  File "/home/airflow/.local/lib/python3.7/site-packages/requests/adapters.py", line 519, in send
    raise ConnectionError(e, request=request)
requests.exceptions.ConnectionError: HTTPSConnectionPool(host='www.mercadobitcoin.net', port=443): Max retries exceeded with url: /api/BTC/day-summary/2022/5/2/ (Caused by NewConnectionError('<urllib3.connection.HTTPSConnection object at 0x7f3e6d1feb90>: Failed to establish a new connection: [Errno -3] Temporary failure in name resolution'))
[2022-07-07 01:09:39,432] {processor.py:653} WARNING - No viable dags retrieved from /opt/airflow/dags/projeto_api.py
[2022-07-07 01:09:40,708] {processor.py:161} INFO - Processing /opt/airflow/dags/projeto_api.py took 10.909 seconds
[2022-07-07 01:10:10,805] {processor.py:153} INFO - Started process (PID=276) to work on /opt/airflow/dags/projeto_api.py
[2022-07-07 01:10:10,830] {processor.py:641} INFO - Processing file /opt/airflow/dags/projeto_api.py for tasks to queue
[2022-07-07 01:10:10,831] {logging_mixin.py:115} INFO - [2022-07-07 01:10:10,831] {dagbag.py:507} INFO - Filling up the DagBag from /opt/airflow/dags/projeto_api.py
[2022-07-07 01:10:16,254] {logging_mixin.py:115} INFO - [2022-07-07 01:10:16,242] {dagbag.py:320} ERROR - Failed to import: /opt/airflow/dags/projeto_api.py
Traceback (most recent call last):
  File "/home/airflow/.local/lib/python3.7/site-packages/urllib3/connection.py", line 175, in _new_conn
    (self._dns_host, self.port), self.timeout, **extra_kw
  File "/home/airflow/.local/lib/python3.7/site-packages/urllib3/util/connection.py", line 72, in create_connection
    for res in socket.getaddrinfo(host, port, family, socket.SOCK_STREAM):
  File "/usr/local/lib/python3.7/socket.py", line 752, in getaddrinfo
    for res in _socket.getaddrinfo(host, port, family, type, proto, flags):
socket.gaierror: [Errno -3] Temporary failure in name resolution

During handling of the above exception, another exception occurred:

Traceback (most recent call last):
  File "/home/airflow/.local/lib/python3.7/site-packages/urllib3/connectionpool.py", line 710, in urlopen
    chunked=chunked,
  File "/home/airflow/.local/lib/python3.7/site-packages/urllib3/connectionpool.py", line 386, in _make_request
    self._validate_conn(conn)
  File "/home/airflow/.local/lib/python3.7/site-packages/urllib3/connectionpool.py", line 1040, in _validate_conn
    conn.connect()
  File "/home/airflow/.local/lib/python3.7/site-packages/urllib3/connection.py", line 358, in connect
    self.sock = conn = self._new_conn()
  File "/home/airflow/.local/lib/python3.7/site-packages/urllib3/connection.py", line 187, in _new_conn
    self, "Failed to establish a new connection: %s" % e
urllib3.exceptions.NewConnectionError: <urllib3.connection.HTTPSConnection object at 0x7f3e6d1fdc10>: Failed to establish a new connection: [Errno -3] Temporary failure in name resolution

During handling of the above exception, another exception occurred:

Traceback (most recent call last):
  File "/home/airflow/.local/lib/python3.7/site-packages/requests/adapters.py", line 450, in send
    timeout=timeout
  File "/home/airflow/.local/lib/python3.7/site-packages/urllib3/connectionpool.py", line 786, in urlopen
    method, url, error=e, _pool=self, _stacktrace=sys.exc_info()[2]
  File "/home/airflow/.local/lib/python3.7/site-packages/urllib3/util/retry.py", line 592, in increment
    raise MaxRetryError(_pool, url, error or ResponseError(cause))
urllib3.exceptions.MaxRetryError: HTTPSConnectionPool(host='www.mercadobitcoin.net', port=443): Max retries exceeded with url: /api/BTC/day-summary/2022/5/2/ (Caused by NewConnectionError('<urllib3.connection.HTTPSConnection object at 0x7f3e6d1fdc10>: Failed to establish a new connection: [Errno -3] Temporary failure in name resolution'))

During handling of the above exception, another exception occurred:

Traceback (most recent call last):
  File "/home/airflow/.local/lib/python3.7/site-packages/airflow/models/dagbag.py", line 317, in parse
    loader.exec_module(new_module)
  File "<frozen importlib._bootstrap_external>", line 728, in exec_module
  File "<frozen importlib._bootstrap>", line 219, in _call_with_frames_removed
  File "/opt/airflow/dags/projeto_api.py", line 26, in <module>
    dia1 = Api_conn.get_api(2, 5, 2022)
  File "/opt/airflow/dags/projeto_api.py", line 19, in get_api
    response_API = requests.get(f'https://www.mercadobitcoin.net/api/BTC/day-summary/{year}/{month}/{day}/')
  File "/home/airflow/.local/lib/python3.7/site-packages/requests/api.py", line 75, in get
    return request('get', url, params=params, **kwargs)
  File "/home/airflow/.local/lib/python3.7/site-packages/requests/api.py", line 61, in request
    return session.request(method=method, url=url, **kwargs)
  File "/home/airflow/.local/lib/python3.7/site-packages/requests/sessions.py", line 529, in request
    resp = self.send(prep, **send_kwargs)
  File "/home/airflow/.local/lib/python3.7/site-packages/requests/sessions.py", line 645, in send
    r = adapter.send(request, **kwargs)
  File "/home/airflow/.local/lib/python3.7/site-packages/requests/adapters.py", line 519, in send
    raise ConnectionError(e, request=request)
requests.exceptions.ConnectionError: HTTPSConnectionPool(host='www.mercadobitcoin.net', port=443): Max retries exceeded with url: /api/BTC/day-summary/2022/5/2/ (Caused by NewConnectionError('<urllib3.connection.HTTPSConnection object at 0x7f3e6d1fdc10>: Failed to establish a new connection: [Errno -3] Temporary failure in name resolution'))
[2022-07-07 01:10:16,255] {processor.py:653} WARNING - No viable dags retrieved from /opt/airflow/dags/projeto_api.py
[2022-07-07 01:10:16,297] {processor.py:161} INFO - Processing /opt/airflow/dags/projeto_api.py took 5.496 seconds
[2022-07-07 01:10:46,435] {processor.py:153} INFO - Started process (PID=295) to work on /opt/airflow/dags/projeto_api.py
[2022-07-07 01:10:46,476] {processor.py:641} INFO - Processing file /opt/airflow/dags/projeto_api.py for tasks to queue
[2022-07-07 01:10:46,477] {logging_mixin.py:115} INFO - [2022-07-07 01:10:46,477] {dagbag.py:507} INFO - Filling up the DagBag from /opt/airflow/dags/projeto_api.py
[2022-07-07 01:10:50,030] {logging_mixin.py:115} INFO - [2022-07-07 01:10:50,024] {dagbag.py:320} ERROR - Failed to import: /opt/airflow/dags/projeto_api.py
Traceback (most recent call last):
  File "/home/airflow/.local/lib/python3.7/site-packages/urllib3/connection.py", line 175, in _new_conn
    (self._dns_host, self.port), self.timeout, **extra_kw
  File "/home/airflow/.local/lib/python3.7/site-packages/urllib3/util/connection.py", line 72, in create_connection
    for res in socket.getaddrinfo(host, port, family, socket.SOCK_STREAM):
  File "/usr/local/lib/python3.7/socket.py", line 752, in getaddrinfo
    for res in _socket.getaddrinfo(host, port, family, type, proto, flags):
socket.gaierror: [Errno -3] Temporary failure in name resolution

During handling of the above exception, another exception occurred:

Traceback (most recent call last):
  File "/home/airflow/.local/lib/python3.7/site-packages/urllib3/connectionpool.py", line 710, in urlopen
    chunked=chunked,
  File "/home/airflow/.local/lib/python3.7/site-packages/urllib3/connectionpool.py", line 386, in _make_request
    self._validate_conn(conn)
  File "/home/airflow/.local/lib/python3.7/site-packages/urllib3/connectionpool.py", line 1040, in _validate_conn
    conn.connect()
  File "/home/airflow/.local/lib/python3.7/site-packages/urllib3/connection.py", line 358, in connect
    self.sock = conn = self._new_conn()
  File "/home/airflow/.local/lib/python3.7/site-packages/urllib3/connection.py", line 187, in _new_conn
    self, "Failed to establish a new connection: %s" % e
urllib3.exceptions.NewConnectionError: <urllib3.connection.HTTPSConnection object at 0x7f3e6d224510>: Failed to establish a new connection: [Errno -3] Temporary failure in name resolution

During handling of the above exception, another exception occurred:

Traceback (most recent call last):
  File "/home/airflow/.local/lib/python3.7/site-packages/requests/adapters.py", line 450, in send
    timeout=timeout
  File "/home/airflow/.local/lib/python3.7/site-packages/urllib3/connectionpool.py", line 786, in urlopen
    method, url, error=e, _pool=self, _stacktrace=sys.exc_info()[2]
  File "/home/airflow/.local/lib/python3.7/site-packages/urllib3/util/retry.py", line 592, in increment
    raise MaxRetryError(_pool, url, error or ResponseError(cause))
urllib3.exceptions.MaxRetryError: HTTPSConnectionPool(host='www.mercadobitcoin.net', port=443): Max retries exceeded with url: /api/BTC/day-summary/2022/5/2/ (Caused by NewConnectionError('<urllib3.connection.HTTPSConnection object at 0x7f3e6d224510>: Failed to establish a new connection: [Errno -3] Temporary failure in name resolution'))

During handling of the above exception, another exception occurred:

Traceback (most recent call last):
  File "/home/airflow/.local/lib/python3.7/site-packages/airflow/models/dagbag.py", line 317, in parse
    loader.exec_module(new_module)
  File "<frozen importlib._bootstrap_external>", line 728, in exec_module
  File "<frozen importlib._bootstrap>", line 219, in _call_with_frames_removed
  File "/opt/airflow/dags/projeto_api.py", line 26, in <module>
    dia1 = Api_conn.get_api(2, 5, 2022)
  File "/opt/airflow/dags/projeto_api.py", line 19, in get_api
    response_API = requests.get(f'https://www.mercadobitcoin.net/api/BTC/day-summary/{year}/{month}/{day}/')
  File "/home/airflow/.local/lib/python3.7/site-packages/requests/api.py", line 75, in get
    return request('get', url, params=params, **kwargs)
  File "/home/airflow/.local/lib/python3.7/site-packages/requests/api.py", line 61, in request
    return session.request(method=method, url=url, **kwargs)
  File "/home/airflow/.local/lib/python3.7/site-packages/requests/sessions.py", line 529, in request
    resp = self.send(prep, **send_kwargs)
  File "/home/airflow/.local/lib/python3.7/site-packages/requests/sessions.py", line 645, in send
    r = adapter.send(request, **kwargs)
  File "/home/airflow/.local/lib/python3.7/site-packages/requests/adapters.py", line 519, in send
    raise ConnectionError(e, request=request)
requests.exceptions.ConnectionError: HTTPSConnectionPool(host='www.mercadobitcoin.net', port=443): Max retries exceeded with url: /api/BTC/day-summary/2022/5/2/ (Caused by NewConnectionError('<urllib3.connection.HTTPSConnection object at 0x7f3e6d224510>: Failed to establish a new connection: [Errno -3] Temporary failure in name resolution'))
[2022-07-07 01:10:50,031] {processor.py:653} WARNING - No viable dags retrieved from /opt/airflow/dags/projeto_api.py
[2022-07-07 01:10:50,122] {processor.py:161} INFO - Processing /opt/airflow/dags/projeto_api.py took 3.668 seconds
[2022-07-07 01:11:20,276] {processor.py:153} INFO - Started process (PID=322) to work on /opt/airflow/dags/projeto_api.py
[2022-07-07 01:11:20,276] {processor.py:641} INFO - Processing file /opt/airflow/dags/projeto_api.py for tasks to queue
[2022-07-07 01:11:20,277] {logging_mixin.py:115} INFO - [2022-07-07 01:11:20,277] {dagbag.py:507} INFO - Filling up the DagBag from /opt/airflow/dags/projeto_api.py
[2022-07-07 01:11:23,818] {logging_mixin.py:115} INFO - [2022-07-07 01:11:23,811] {dagbag.py:320} ERROR - Failed to import: /opt/airflow/dags/projeto_api.py
Traceback (most recent call last):
  File "/home/airflow/.local/lib/python3.7/site-packages/urllib3/connection.py", line 175, in _new_conn
    (self._dns_host, self.port), self.timeout, **extra_kw
  File "/home/airflow/.local/lib/python3.7/site-packages/urllib3/util/connection.py", line 72, in create_connection
    for res in socket.getaddrinfo(host, port, family, socket.SOCK_STREAM):
  File "/usr/local/lib/python3.7/socket.py", line 752, in getaddrinfo
    for res in _socket.getaddrinfo(host, port, family, type, proto, flags):
socket.gaierror: [Errno -3] Temporary failure in name resolution

During handling of the above exception, another exception occurred:

Traceback (most recent call last):
  File "/home/airflow/.local/lib/python3.7/site-packages/urllib3/connectionpool.py", line 710, in urlopen
    chunked=chunked,
  File "/home/airflow/.local/lib/python3.7/site-packages/urllib3/connectionpool.py", line 386, in _make_request
    self._validate_conn(conn)
  File "/home/airflow/.local/lib/python3.7/site-packages/urllib3/connectionpool.py", line 1040, in _validate_conn
    conn.connect()
  File "/home/airflow/.local/lib/python3.7/site-packages/urllib3/connection.py", line 358, in connect
    self.sock = conn = self._new_conn()
  File "/home/airflow/.local/lib/python3.7/site-packages/urllib3/connection.py", line 187, in _new_conn
    self, "Failed to establish a new connection: %s" % e
urllib3.exceptions.NewConnectionError: <urllib3.connection.HTTPSConnection object at 0x7f3e6d224550>: Failed to establish a new connection: [Errno -3] Temporary failure in name resolution

During handling of the above exception, another exception occurred:

Traceback (most recent call last):
  File "/home/airflow/.local/lib/python3.7/site-packages/requests/adapters.py", line 450, in send
    timeout=timeout
  File "/home/airflow/.local/lib/python3.7/site-packages/urllib3/connectionpool.py", line 786, in urlopen
    method, url, error=e, _pool=self, _stacktrace=sys.exc_info()[2]
  File "/home/airflow/.local/lib/python3.7/site-packages/urllib3/util/retry.py", line 592, in increment
    raise MaxRetryError(_pool, url, error or ResponseError(cause))
urllib3.exceptions.MaxRetryError: HTTPSConnectionPool(host='www.mercadobitcoin.net', port=443): Max retries exceeded with url: /api/BTC/day-summary/2022/5/2/ (Caused by NewConnectionError('<urllib3.connection.HTTPSConnection object at 0x7f3e6d224550>: Failed to establish a new connection: [Errno -3] Temporary failure in name resolution'))

During handling of the above exception, another exception occurred:

Traceback (most recent call last):
  File "/home/airflow/.local/lib/python3.7/site-packages/airflow/models/dagbag.py", line 317, in parse
    loader.exec_module(new_module)
  File "<frozen importlib._bootstrap_external>", line 728, in exec_module
  File "<frozen importlib._bootstrap>", line 219, in _call_with_frames_removed
  File "/opt/airflow/dags/projeto_api.py", line 26, in <module>
    dia1 = Api_conn.get_api(2, 5, 2022)
  File "/opt/airflow/dags/projeto_api.py", line 19, in get_api
    response_API = requests.get(f'https://www.mercadobitcoin.net/api/BTC/day-summary/{year}/{month}/{day}/')
  File "/home/airflow/.local/lib/python3.7/site-packages/requests/api.py", line 75, in get
    return request('get', url, params=params, **kwargs)
  File "/home/airflow/.local/lib/python3.7/site-packages/requests/api.py", line 61, in request
    return session.request(method=method, url=url, **kwargs)
  File "/home/airflow/.local/lib/python3.7/site-packages/requests/sessions.py", line 529, in request
    resp = self.send(prep, **send_kwargs)
  File "/home/airflow/.local/lib/python3.7/site-packages/requests/sessions.py", line 645, in send
    r = adapter.send(request, **kwargs)
  File "/home/airflow/.local/lib/python3.7/site-packages/requests/adapters.py", line 519, in send
    raise ConnectionError(e, request=request)
requests.exceptions.ConnectionError: HTTPSConnectionPool(host='www.mercadobitcoin.net', port=443): Max retries exceeded with url: /api/BTC/day-summary/2022/5/2/ (Caused by NewConnectionError('<urllib3.connection.HTTPSConnection object at 0x7f3e6d224550>: Failed to establish a new connection: [Errno -3] Temporary failure in name resolution'))
[2022-07-07 01:11:23,819] {processor.py:653} WARNING - No viable dags retrieved from /opt/airflow/dags/projeto_api.py
[2022-07-07 01:11:23,880] {processor.py:161} INFO - Processing /opt/airflow/dags/projeto_api.py took 3.608 seconds
[2022-07-07 01:11:53,964] {processor.py:153} INFO - Started process (PID=352) to work on /opt/airflow/dags/projeto_api.py
[2022-07-07 01:11:53,965] {processor.py:641} INFO - Processing file /opt/airflow/dags/projeto_api.py for tasks to queue
[2022-07-07 01:11:53,966] {logging_mixin.py:115} INFO - [2022-07-07 01:11:53,966] {dagbag.py:507} INFO - Filling up the DagBag from /opt/airflow/dags/projeto_api.py
[2022-07-07 01:11:57,612] {logging_mixin.py:115} INFO - [2022-07-07 01:11:57,604] {dagbag.py:320} ERROR - Failed to import: /opt/airflow/dags/projeto_api.py
Traceback (most recent call last):
  File "/home/airflow/.local/lib/python3.7/site-packages/urllib3/connection.py", line 175, in _new_conn
    (self._dns_host, self.port), self.timeout, **extra_kw
  File "/home/airflow/.local/lib/python3.7/site-packages/urllib3/util/connection.py", line 72, in create_connection
    for res in socket.getaddrinfo(host, port, family, socket.SOCK_STREAM):
  File "/usr/local/lib/python3.7/socket.py", line 752, in getaddrinfo
    for res in _socket.getaddrinfo(host, port, family, type, proto, flags):
socket.gaierror: [Errno -3] Temporary failure in name resolution

During handling of the above exception, another exception occurred:

Traceback (most recent call last):
  File "/home/airflow/.local/lib/python3.7/site-packages/urllib3/connectionpool.py", line 710, in urlopen
    chunked=chunked,
  File "/home/airflow/.local/lib/python3.7/site-packages/urllib3/connectionpool.py", line 386, in _make_request
    self._validate_conn(conn)
  File "/home/airflow/.local/lib/python3.7/site-packages/urllib3/connectionpool.py", line 1040, in _validate_conn
    conn.connect()
  File "/home/airflow/.local/lib/python3.7/site-packages/urllib3/connection.py", line 358, in connect
    self.sock = conn = self._new_conn()
  File "/home/airflow/.local/lib/python3.7/site-packages/urllib3/connection.py", line 187, in _new_conn
    self, "Failed to establish a new connection: %s" % e
urllib3.exceptions.NewConnectionError: <urllib3.connection.HTTPSConnection object at 0x7f3e6d2215d0>: Failed to establish a new connection: [Errno -3] Temporary failure in name resolution

During handling of the above exception, another exception occurred:

Traceback (most recent call last):
  File "/home/airflow/.local/lib/python3.7/site-packages/requests/adapters.py", line 450, in send
    timeout=timeout
  File "/home/airflow/.local/lib/python3.7/site-packages/urllib3/connectionpool.py", line 786, in urlopen
    method, url, error=e, _pool=self, _stacktrace=sys.exc_info()[2]
  File "/home/airflow/.local/lib/python3.7/site-packages/urllib3/util/retry.py", line 592, in increment
    raise MaxRetryError(_pool, url, error or ResponseError(cause))
urllib3.exceptions.MaxRetryError: HTTPSConnectionPool(host='www.mercadobitcoin.net', port=443): Max retries exceeded with url: /api/BTC/day-summary/2022/5/2/ (Caused by NewConnectionError('<urllib3.connection.HTTPSConnection object at 0x7f3e6d2215d0>: Failed to establish a new connection: [Errno -3] Temporary failure in name resolution'))

During handling of the above exception, another exception occurred:

Traceback (most recent call last):
  File "/home/airflow/.local/lib/python3.7/site-packages/airflow/models/dagbag.py", line 317, in parse
    loader.exec_module(new_module)
  File "<frozen importlib._bootstrap_external>", line 728, in exec_module
  File "<frozen importlib._bootstrap>", line 219, in _call_with_frames_removed
  File "/opt/airflow/dags/projeto_api.py", line 26, in <module>
    dia1 = Api_conn.get_api(2, 5, 2022)
  File "/opt/airflow/dags/projeto_api.py", line 19, in get_api
    response_API = requests.get(f'https://www.mercadobitcoin.net/api/BTC/day-summary/{year}/{month}/{day}/')
  File "/home/airflow/.local/lib/python3.7/site-packages/requests/api.py", line 75, in get
    return request('get', url, params=params, **kwargs)
  File "/home/airflow/.local/lib/python3.7/site-packages/requests/api.py", line 61, in request
    return session.request(method=method, url=url, **kwargs)
  File "/home/airflow/.local/lib/python3.7/site-packages/requests/sessions.py", line 529, in request
    resp = self.send(prep, **send_kwargs)
  File "/home/airflow/.local/lib/python3.7/site-packages/requests/sessions.py", line 645, in send
    r = adapter.send(request, **kwargs)
  File "/home/airflow/.local/lib/python3.7/site-packages/requests/adapters.py", line 519, in send
    raise ConnectionError(e, request=request)
requests.exceptions.ConnectionError: HTTPSConnectionPool(host='www.mercadobitcoin.net', port=443): Max retries exceeded with url: /api/BTC/day-summary/2022/5/2/ (Caused by NewConnectionError('<urllib3.connection.HTTPSConnection object at 0x7f3e6d2215d0>: Failed to establish a new connection: [Errno -3] Temporary failure in name resolution'))
[2022-07-07 01:11:57,613] {processor.py:653} WARNING - No viable dags retrieved from /opt/airflow/dags/projeto_api.py
[2022-07-07 01:11:57,677] {processor.py:161} INFO - Processing /opt/airflow/dags/projeto_api.py took 3.717 seconds
[2022-07-07 01:12:27,807] {processor.py:153} INFO - Started process (PID=378) to work on /opt/airflow/dags/projeto_api.py
[2022-07-07 01:12:27,808] {processor.py:641} INFO - Processing file /opt/airflow/dags/projeto_api.py for tasks to queue
[2022-07-07 01:12:27,809] {logging_mixin.py:115} INFO - [2022-07-07 01:12:27,808] {dagbag.py:507} INFO - Filling up the DagBag from /opt/airflow/dags/projeto_api.py
[2022-07-07 01:12:31,403] {logging_mixin.py:115} INFO - [2022-07-07 01:12:31,396] {dagbag.py:320} ERROR - Failed to import: /opt/airflow/dags/projeto_api.py
Traceback (most recent call last):
  File "/home/airflow/.local/lib/python3.7/site-packages/urllib3/connection.py", line 175, in _new_conn
    (self._dns_host, self.port), self.timeout, **extra_kw
  File "/home/airflow/.local/lib/python3.7/site-packages/urllib3/util/connection.py", line 72, in create_connection
    for res in socket.getaddrinfo(host, port, family, socket.SOCK_STREAM):
  File "/usr/local/lib/python3.7/socket.py", line 752, in getaddrinfo
    for res in _socket.getaddrinfo(host, port, family, type, proto, flags):
socket.gaierror: [Errno -3] Temporary failure in name resolution

During handling of the above exception, another exception occurred:

Traceback (most recent call last):
  File "/home/airflow/.local/lib/python3.7/site-packages/urllib3/connectionpool.py", line 710, in urlopen
    chunked=chunked,
  File "/home/airflow/.local/lib/python3.7/site-packages/urllib3/connectionpool.py", line 386, in _make_request
    self._validate_conn(conn)
  File "/home/airflow/.local/lib/python3.7/site-packages/urllib3/connectionpool.py", line 1040, in _validate_conn
    conn.connect()
  File "/home/airflow/.local/lib/python3.7/site-packages/urllib3/connection.py", line 358, in connect
    self.sock = conn = self._new_conn()
  File "/home/airflow/.local/lib/python3.7/site-packages/urllib3/connection.py", line 187, in _new_conn
    self, "Failed to establish a new connection: %s" % e
urllib3.exceptions.NewConnectionError: <urllib3.connection.HTTPSConnection object at 0x7f3e6d2215d0>: Failed to establish a new connection: [Errno -3] Temporary failure in name resolution

During handling of the above exception, another exception occurred:

Traceback (most recent call last):
  File "/home/airflow/.local/lib/python3.7/site-packages/requests/adapters.py", line 450, in send
    timeout=timeout
  File "/home/airflow/.local/lib/python3.7/site-packages/urllib3/connectionpool.py", line 786, in urlopen
    method, url, error=e, _pool=self, _stacktrace=sys.exc_info()[2]
  File "/home/airflow/.local/lib/python3.7/site-packages/urllib3/util/retry.py", line 592, in increment
    raise MaxRetryError(_pool, url, error or ResponseError(cause))
urllib3.exceptions.MaxRetryError: HTTPSConnectionPool(host='www.mercadobitcoin.net', port=443): Max retries exceeded with url: /api/BTC/day-summary/2022/5/2/ (Caused by NewConnectionError('<urllib3.connection.HTTPSConnection object at 0x7f3e6d2215d0>: Failed to establish a new connection: [Errno -3] Temporary failure in name resolution'))

During handling of the above exception, another exception occurred:

Traceback (most recent call last):
  File "/home/airflow/.local/lib/python3.7/site-packages/airflow/models/dagbag.py", line 317, in parse
    loader.exec_module(new_module)
  File "<frozen importlib._bootstrap_external>", line 728, in exec_module
  File "<frozen importlib._bootstrap>", line 219, in _call_with_frames_removed
  File "/opt/airflow/dags/projeto_api.py", line 26, in <module>
    dia1 = Api_conn.get_api(2, 5, 2022)
  File "/opt/airflow/dags/projeto_api.py", line 19, in get_api
    response_API = requests.get(f'https://www.mercadobitcoin.net/api/BTC/day-summary/{year}/{month}/{day}/')
  File "/home/airflow/.local/lib/python3.7/site-packages/requests/api.py", line 75, in get
    return request('get', url, params=params, **kwargs)
  File "/home/airflow/.local/lib/python3.7/site-packages/requests/api.py", line 61, in request
    return session.request(method=method, url=url, **kwargs)
  File "/home/airflow/.local/lib/python3.7/site-packages/requests/sessions.py", line 529, in request
    resp = self.send(prep, **send_kwargs)
  File "/home/airflow/.local/lib/python3.7/site-packages/requests/sessions.py", line 645, in send
    r = adapter.send(request, **kwargs)
  File "/home/airflow/.local/lib/python3.7/site-packages/requests/adapters.py", line 519, in send
    raise ConnectionError(e, request=request)
requests.exceptions.ConnectionError: HTTPSConnectionPool(host='www.mercadobitcoin.net', port=443): Max retries exceeded with url: /api/BTC/day-summary/2022/5/2/ (Caused by NewConnectionError('<urllib3.connection.HTTPSConnection object at 0x7f3e6d2215d0>: Failed to establish a new connection: [Errno -3] Temporary failure in name resolution'))
[2022-07-07 01:12:31,405] {processor.py:653} WARNING - No viable dags retrieved from /opt/airflow/dags/projeto_api.py
[2022-07-07 01:12:31,464] {processor.py:161} INFO - Processing /opt/airflow/dags/projeto_api.py took 3.661 seconds
[2022-07-07 01:13:01,537] {processor.py:153} INFO - Started process (PID=398) to work on /opt/airflow/dags/projeto_api.py
[2022-07-07 01:13:01,538] {processor.py:641} INFO - Processing file /opt/airflow/dags/projeto_api.py for tasks to queue
[2022-07-07 01:13:01,538] {logging_mixin.py:115} INFO - [2022-07-07 01:13:01,538] {dagbag.py:507} INFO - Filling up the DagBag from /opt/airflow/dags/projeto_api.py
[2022-07-07 01:13:05,190] {logging_mixin.py:115} INFO - [2022-07-07 01:13:05,186] {dagbag.py:320} ERROR - Failed to import: /opt/airflow/dags/projeto_api.py
Traceback (most recent call last):
  File "/home/airflow/.local/lib/python3.7/site-packages/urllib3/connection.py", line 175, in _new_conn
    (self._dns_host, self.port), self.timeout, **extra_kw
  File "/home/airflow/.local/lib/python3.7/site-packages/urllib3/util/connection.py", line 72, in create_connection
    for res in socket.getaddrinfo(host, port, family, socket.SOCK_STREAM):
  File "/usr/local/lib/python3.7/socket.py", line 752, in getaddrinfo
    for res in _socket.getaddrinfo(host, port, family, type, proto, flags):
socket.gaierror: [Errno -3] Temporary failure in name resolution

During handling of the above exception, another exception occurred:

Traceback (most recent call last):
  File "/home/airflow/.local/lib/python3.7/site-packages/urllib3/connectionpool.py", line 710, in urlopen
    chunked=chunked,
  File "/home/airflow/.local/lib/python3.7/site-packages/urllib3/connectionpool.py", line 386, in _make_request
    self._validate_conn(conn)
  File "/home/airflow/.local/lib/python3.7/site-packages/urllib3/connectionpool.py", line 1040, in _validate_conn
    conn.connect()
  File "/home/airflow/.local/lib/python3.7/site-packages/urllib3/connection.py", line 358, in connect
    self.sock = conn = self._new_conn()
  File "/home/airflow/.local/lib/python3.7/site-packages/urllib3/connection.py", line 187, in _new_conn
    self, "Failed to establish a new connection: %s" % e
urllib3.exceptions.NewConnectionError: <urllib3.connection.HTTPSConnection object at 0x7f3e6d221590>: Failed to establish a new connection: [Errno -3] Temporary failure in name resolution

During handling of the above exception, another exception occurred:

Traceback (most recent call last):
  File "/home/airflow/.local/lib/python3.7/site-packages/requests/adapters.py", line 450, in send
    timeout=timeout
  File "/home/airflow/.local/lib/python3.7/site-packages/urllib3/connectionpool.py", line 786, in urlopen
    method, url, error=e, _pool=self, _stacktrace=sys.exc_info()[2]
  File "/home/airflow/.local/lib/python3.7/site-packages/urllib3/util/retry.py", line 592, in increment
    raise MaxRetryError(_pool, url, error or ResponseError(cause))
urllib3.exceptions.MaxRetryError: HTTPSConnectionPool(host='www.mercadobitcoin.net', port=443): Max retries exceeded with url: /api/BTC/day-summary/2022/5/2/ (Caused by NewConnectionError('<urllib3.connection.HTTPSConnection object at 0x7f3e6d221590>: Failed to establish a new connection: [Errno -3] Temporary failure in name resolution'))

During handling of the above exception, another exception occurred:

Traceback (most recent call last):
  File "/home/airflow/.local/lib/python3.7/site-packages/airflow/models/dagbag.py", line 317, in parse
    loader.exec_module(new_module)
  File "<frozen importlib._bootstrap_external>", line 728, in exec_module
  File "<frozen importlib._bootstrap>", line 219, in _call_with_frames_removed
  File "/opt/airflow/dags/projeto_api.py", line 26, in <module>
    dia1 = Api_conn.get_api(2, 5, 2022)
  File "/opt/airflow/dags/projeto_api.py", line 19, in get_api
    response_API = requests.get(f'https://www.mercadobitcoin.net/api/BTC/day-summary/{year}/{month}/{day}/')
  File "/home/airflow/.local/lib/python3.7/site-packages/requests/api.py", line 75, in get
    return request('get', url, params=params, **kwargs)
  File "/home/airflow/.local/lib/python3.7/site-packages/requests/api.py", line 61, in request
    return session.request(method=method, url=url, **kwargs)
  File "/home/airflow/.local/lib/python3.7/site-packages/requests/sessions.py", line 529, in request
    resp = self.send(prep, **send_kwargs)
  File "/home/airflow/.local/lib/python3.7/site-packages/requests/sessions.py", line 645, in send
    r = adapter.send(request, **kwargs)
  File "/home/airflow/.local/lib/python3.7/site-packages/requests/adapters.py", line 519, in send
    raise ConnectionError(e, request=request)
requests.exceptions.ConnectionError: HTTPSConnectionPool(host='www.mercadobitcoin.net', port=443): Max retries exceeded with url: /api/BTC/day-summary/2022/5/2/ (Caused by NewConnectionError('<urllib3.connection.HTTPSConnection object at 0x7f3e6d221590>: Failed to establish a new connection: [Errno -3] Temporary failure in name resolution'))
[2022-07-07 01:13:05,190] {processor.py:653} WARNING - No viable dags retrieved from /opt/airflow/dags/projeto_api.py
[2022-07-07 01:13:05,283] {processor.py:161} INFO - Processing /opt/airflow/dags/projeto_api.py took 3.749 seconds
[2022-07-07 01:13:35,378] {processor.py:153} INFO - Started process (PID=427) to work on /opt/airflow/dags/projeto_api.py
[2022-07-07 01:13:35,378] {processor.py:641} INFO - Processing file /opt/airflow/dags/projeto_api.py for tasks to queue
[2022-07-07 01:13:35,379] {logging_mixin.py:115} INFO - [2022-07-07 01:13:35,379] {dagbag.py:507} INFO - Filling up the DagBag from /opt/airflow/dags/projeto_api.py
[2022-07-07 01:13:41,065] {logging_mixin.py:115} INFO - [2022-07-07 01:13:41,059] {dagbag.py:320} ERROR - Failed to import: /opt/airflow/dags/projeto_api.py
Traceback (most recent call last):
  File "/home/airflow/.local/lib/python3.7/site-packages/urllib3/connection.py", line 175, in _new_conn
    (self._dns_host, self.port), self.timeout, **extra_kw
  File "/home/airflow/.local/lib/python3.7/site-packages/urllib3/util/connection.py", line 72, in create_connection
    for res in socket.getaddrinfo(host, port, family, socket.SOCK_STREAM):
  File "/usr/local/lib/python3.7/socket.py", line 752, in getaddrinfo
    for res in _socket.getaddrinfo(host, port, family, type, proto, flags):
socket.gaierror: [Errno -3] Temporary failure in name resolution

During handling of the above exception, another exception occurred:

Traceback (most recent call last):
  File "/home/airflow/.local/lib/python3.7/site-packages/urllib3/connectionpool.py", line 710, in urlopen
    chunked=chunked,
  File "/home/airflow/.local/lib/python3.7/site-packages/urllib3/connectionpool.py", line 386, in _make_request
    self._validate_conn(conn)
  File "/home/airflow/.local/lib/python3.7/site-packages/urllib3/connectionpool.py", line 1040, in _validate_conn
    conn.connect()
  File "/home/airflow/.local/lib/python3.7/site-packages/urllib3/connection.py", line 358, in connect
    self.sock = conn = self._new_conn()
  File "/home/airflow/.local/lib/python3.7/site-packages/urllib3/connection.py", line 187, in _new_conn
    self, "Failed to establish a new connection: %s" % e
urllib3.exceptions.NewConnectionError: <urllib3.connection.HTTPSConnection object at 0x7f3e6d221610>: Failed to establish a new connection: [Errno -3] Temporary failure in name resolution

During handling of the above exception, another exception occurred:

Traceback (most recent call last):
  File "/home/airflow/.local/lib/python3.7/site-packages/requests/adapters.py", line 450, in send
    timeout=timeout
  File "/home/airflow/.local/lib/python3.7/site-packages/urllib3/connectionpool.py", line 786, in urlopen
    method, url, error=e, _pool=self, _stacktrace=sys.exc_info()[2]
  File "/home/airflow/.local/lib/python3.7/site-packages/urllib3/util/retry.py", line 592, in increment
    raise MaxRetryError(_pool, url, error or ResponseError(cause))
urllib3.exceptions.MaxRetryError: HTTPSConnectionPool(host='www.mercadobitcoin.net', port=443): Max retries exceeded with url: /api/BTC/day-summary/2022/5/2/ (Caused by NewConnectionError('<urllib3.connection.HTTPSConnection object at 0x7f3e6d221610>: Failed to establish a new connection: [Errno -3] Temporary failure in name resolution'))

During handling of the above exception, another exception occurred:

Traceback (most recent call last):
  File "/home/airflow/.local/lib/python3.7/site-packages/airflow/models/dagbag.py", line 317, in parse
    loader.exec_module(new_module)
  File "<frozen importlib._bootstrap_external>", line 728, in exec_module
  File "<frozen importlib._bootstrap>", line 219, in _call_with_frames_removed
  File "/opt/airflow/dags/projeto_api.py", line 26, in <module>
    dia1 = Api_conn.get_api(2, 5, 2022)
  File "/opt/airflow/dags/projeto_api.py", line 19, in get_api
    response_API = requests.get(f'https://www.mercadobitcoin.net/api/BTC/day-summary/{year}/{month}/{day}/')
  File "/home/airflow/.local/lib/python3.7/site-packages/requests/api.py", line 75, in get
    return request('get', url, params=params, **kwargs)
  File "/home/airflow/.local/lib/python3.7/site-packages/requests/api.py", line 61, in request
    return session.request(method=method, url=url, **kwargs)
  File "/home/airflow/.local/lib/python3.7/site-packages/requests/sessions.py", line 529, in request
    resp = self.send(prep, **send_kwargs)
  File "/home/airflow/.local/lib/python3.7/site-packages/requests/sessions.py", line 645, in send
    r = adapter.send(request, **kwargs)
  File "/home/airflow/.local/lib/python3.7/site-packages/requests/adapters.py", line 519, in send
    raise ConnectionError(e, request=request)
requests.exceptions.ConnectionError: HTTPSConnectionPool(host='www.mercadobitcoin.net', port=443): Max retries exceeded with url: /api/BTC/day-summary/2022/5/2/ (Caused by NewConnectionError('<urllib3.connection.HTTPSConnection object at 0x7f3e6d221610>: Failed to establish a new connection: [Errno -3] Temporary failure in name resolution'))
[2022-07-07 01:13:41,065] {processor.py:653} WARNING - No viable dags retrieved from /opt/airflow/dags/projeto_api.py
[2022-07-07 01:13:41,094] {processor.py:161} INFO - Processing /opt/airflow/dags/projeto_api.py took 5.720 seconds
[2022-07-07 01:14:11,217] {processor.py:153} INFO - Started process (PID=455) to work on /opt/airflow/dags/projeto_api.py
[2022-07-07 01:14:11,218] {processor.py:641} INFO - Processing file /opt/airflow/dags/projeto_api.py for tasks to queue
[2022-07-07 01:14:11,219] {logging_mixin.py:115} INFO - [2022-07-07 01:14:11,219] {dagbag.py:507} INFO - Filling up the DagBag from /opt/airflow/dags/projeto_api.py
[2022-07-07 01:14:17,415] {logging_mixin.py:115} INFO - [2022-07-07 01:14:17,412] {dagbag.py:320} ERROR - Failed to import: /opt/airflow/dags/projeto_api.py
Traceback (most recent call last):
  File "/home/airflow/.local/lib/python3.7/site-packages/urllib3/connection.py", line 175, in _new_conn
    (self._dns_host, self.port), self.timeout, **extra_kw
  File "/home/airflow/.local/lib/python3.7/site-packages/urllib3/util/connection.py", line 72, in create_connection
    for res in socket.getaddrinfo(host, port, family, socket.SOCK_STREAM):
  File "/usr/local/lib/python3.7/socket.py", line 752, in getaddrinfo
    for res in _socket.getaddrinfo(host, port, family, type, proto, flags):
socket.gaierror: [Errno -3] Temporary failure in name resolution

During handling of the above exception, another exception occurred:

Traceback (most recent call last):
  File "/home/airflow/.local/lib/python3.7/site-packages/urllib3/connectionpool.py", line 710, in urlopen
    chunked=chunked,
  File "/home/airflow/.local/lib/python3.7/site-packages/urllib3/connectionpool.py", line 386, in _make_request
    self._validate_conn(conn)
  File "/home/airflow/.local/lib/python3.7/site-packages/urllib3/connectionpool.py", line 1040, in _validate_conn
    conn.connect()
  File "/home/airflow/.local/lib/python3.7/site-packages/urllib3/connection.py", line 358, in connect
    self.sock = conn = self._new_conn()
  File "/home/airflow/.local/lib/python3.7/site-packages/urllib3/connection.py", line 187, in _new_conn
    self, "Failed to establish a new connection: %s" % e
urllib3.exceptions.NewConnectionError: <urllib3.connection.HTTPSConnection object at 0x7f3e6d2215d0>: Failed to establish a new connection: [Errno -3] Temporary failure in name resolution

During handling of the above exception, another exception occurred:

Traceback (most recent call last):
  File "/home/airflow/.local/lib/python3.7/site-packages/requests/adapters.py", line 450, in send
    timeout=timeout
  File "/home/airflow/.local/lib/python3.7/site-packages/urllib3/connectionpool.py", line 786, in urlopen
    method, url, error=e, _pool=self, _stacktrace=sys.exc_info()[2]
  File "/home/airflow/.local/lib/python3.7/site-packages/urllib3/util/retry.py", line 592, in increment
    raise MaxRetryError(_pool, url, error or ResponseError(cause))
urllib3.exceptions.MaxRetryError: HTTPSConnectionPool(host='www.mercadobitcoin.net', port=443): Max retries exceeded with url: /api/BTC/day-summary/2022/5/2/ (Caused by NewConnectionError('<urllib3.connection.HTTPSConnection object at 0x7f3e6d2215d0>: Failed to establish a new connection: [Errno -3] Temporary failure in name resolution'))

During handling of the above exception, another exception occurred:

Traceback (most recent call last):
  File "/home/airflow/.local/lib/python3.7/site-packages/airflow/models/dagbag.py", line 317, in parse
    loader.exec_module(new_module)
  File "<frozen importlib._bootstrap_external>", line 728, in exec_module
  File "<frozen importlib._bootstrap>", line 219, in _call_with_frames_removed
  File "/opt/airflow/dags/projeto_api.py", line 26, in <module>
    dia1 = Api_conn.get_api(2, 5, 2022)
  File "/opt/airflow/dags/projeto_api.py", line 19, in get_api
    response_API = requests.get(f'https://www.mercadobitcoin.net/api/BTC/day-summary/{year}/{month}/{day}/')
  File "/home/airflow/.local/lib/python3.7/site-packages/requests/api.py", line 75, in get
    return request('get', url, params=params, **kwargs)
  File "/home/airflow/.local/lib/python3.7/site-packages/requests/api.py", line 61, in request
    return session.request(method=method, url=url, **kwargs)
  File "/home/airflow/.local/lib/python3.7/site-packages/requests/sessions.py", line 529, in request
    resp = self.send(prep, **send_kwargs)
  File "/home/airflow/.local/lib/python3.7/site-packages/requests/sessions.py", line 645, in send
    r = adapter.send(request, **kwargs)
  File "/home/airflow/.local/lib/python3.7/site-packages/requests/adapters.py", line 519, in send
    raise ConnectionError(e, request=request)
requests.exceptions.ConnectionError: HTTPSConnectionPool(host='www.mercadobitcoin.net', port=443): Max retries exceeded with url: /api/BTC/day-summary/2022/5/2/ (Caused by NewConnectionError('<urllib3.connection.HTTPSConnection object at 0x7f3e6d2215d0>: Failed to establish a new connection: [Errno -3] Temporary failure in name resolution'))
[2022-07-07 01:14:17,415] {processor.py:653} WARNING - No viable dags retrieved from /opt/airflow/dags/projeto_api.py
[2022-07-07 01:14:17,471] {processor.py:161} INFO - Processing /opt/airflow/dags/projeto_api.py took 6.264 seconds
[2022-07-07 01:14:47,571] {processor.py:153} INFO - Started process (PID=483) to work on /opt/airflow/dags/projeto_api.py
[2022-07-07 01:14:47,572] {processor.py:641} INFO - Processing file /opt/airflow/dags/projeto_api.py for tasks to queue
[2022-07-07 01:14:47,573] {logging_mixin.py:115} INFO - [2022-07-07 01:14:47,573] {dagbag.py:507} INFO - Filling up the DagBag from /opt/airflow/dags/projeto_api.py
[2022-07-07 01:14:51,260] {logging_mixin.py:115} INFO - [2022-07-07 01:14:51,258] {dagbag.py:320} ERROR - Failed to import: /opt/airflow/dags/projeto_api.py
Traceback (most recent call last):
  File "/home/airflow/.local/lib/python3.7/site-packages/urllib3/connection.py", line 175, in _new_conn
    (self._dns_host, self.port), self.timeout, **extra_kw
  File "/home/airflow/.local/lib/python3.7/site-packages/urllib3/util/connection.py", line 72, in create_connection
    for res in socket.getaddrinfo(host, port, family, socket.SOCK_STREAM):
  File "/usr/local/lib/python3.7/socket.py", line 752, in getaddrinfo
    for res in _socket.getaddrinfo(host, port, family, type, proto, flags):
socket.gaierror: [Errno -3] Temporary failure in name resolution

During handling of the above exception, another exception occurred:

Traceback (most recent call last):
  File "/home/airflow/.local/lib/python3.7/site-packages/urllib3/connectionpool.py", line 710, in urlopen
    chunked=chunked,
  File "/home/airflow/.local/lib/python3.7/site-packages/urllib3/connectionpool.py", line 386, in _make_request
    self._validate_conn(conn)
  File "/home/airflow/.local/lib/python3.7/site-packages/urllib3/connectionpool.py", line 1040, in _validate_conn
    conn.connect()
  File "/home/airflow/.local/lib/python3.7/site-packages/urllib3/connection.py", line 358, in connect
    self.sock = conn = self._new_conn()
  File "/home/airflow/.local/lib/python3.7/site-packages/urllib3/connection.py", line 187, in _new_conn
    self, "Failed to establish a new connection: %s" % e
urllib3.exceptions.NewConnectionError: <urllib3.connection.HTTPSConnection object at 0x7f3e6d224550>: Failed to establish a new connection: [Errno -3] Temporary failure in name resolution

During handling of the above exception, another exception occurred:

Traceback (most recent call last):
  File "/home/airflow/.local/lib/python3.7/site-packages/requests/adapters.py", line 450, in send
    timeout=timeout
  File "/home/airflow/.local/lib/python3.7/site-packages/urllib3/connectionpool.py", line 786, in urlopen
    method, url, error=e, _pool=self, _stacktrace=sys.exc_info()[2]
  File "/home/airflow/.local/lib/python3.7/site-packages/urllib3/util/retry.py", line 592, in increment
    raise MaxRetryError(_pool, url, error or ResponseError(cause))
urllib3.exceptions.MaxRetryError: HTTPSConnectionPool(host='www.mercadobitcoin.net', port=443): Max retries exceeded with url: /api/BTC/day-summary/2022/5/2/ (Caused by NewConnectionError('<urllib3.connection.HTTPSConnection object at 0x7f3e6d224550>: Failed to establish a new connection: [Errno -3] Temporary failure in name resolution'))

During handling of the above exception, another exception occurred:

Traceback (most recent call last):
  File "/home/airflow/.local/lib/python3.7/site-packages/airflow/models/dagbag.py", line 317, in parse
    loader.exec_module(new_module)
  File "<frozen importlib._bootstrap_external>", line 728, in exec_module
  File "<frozen importlib._bootstrap>", line 219, in _call_with_frames_removed
  File "/opt/airflow/dags/projeto_api.py", line 26, in <module>
    dia1 = Api_conn.get_api(2, 5, 2022)
  File "/opt/airflow/dags/projeto_api.py", line 19, in get_api
    response_API = requests.get(f'https://www.mercadobitcoin.net/api/BTC/day-summary/{year}/{month}/{day}/')
  File "/home/airflow/.local/lib/python3.7/site-packages/requests/api.py", line 75, in get
    return request('get', url, params=params, **kwargs)
  File "/home/airflow/.local/lib/python3.7/site-packages/requests/api.py", line 61, in request
    return session.request(method=method, url=url, **kwargs)
  File "/home/airflow/.local/lib/python3.7/site-packages/requests/sessions.py", line 529, in request
    resp = self.send(prep, **send_kwargs)
  File "/home/airflow/.local/lib/python3.7/site-packages/requests/sessions.py", line 645, in send
    r = adapter.send(request, **kwargs)
  File "/home/airflow/.local/lib/python3.7/site-packages/requests/adapters.py", line 519, in send
    raise ConnectionError(e, request=request)
requests.exceptions.ConnectionError: HTTPSConnectionPool(host='www.mercadobitcoin.net', port=443): Max retries exceeded with url: /api/BTC/day-summary/2022/5/2/ (Caused by NewConnectionError('<urllib3.connection.HTTPSConnection object at 0x7f3e6d224550>: Failed to establish a new connection: [Errno -3] Temporary failure in name resolution'))
[2022-07-07 01:14:51,261] {processor.py:653} WARNING - No viable dags retrieved from /opt/airflow/dags/projeto_api.py
[2022-07-07 01:14:51,290] {processor.py:161} INFO - Processing /opt/airflow/dags/projeto_api.py took 3.723 seconds
[2022-07-07 01:15:21,372] {processor.py:153} INFO - Started process (PID=502) to work on /opt/airflow/dags/projeto_api.py
[2022-07-07 01:15:21,373] {processor.py:641} INFO - Processing file /opt/airflow/dags/projeto_api.py for tasks to queue
[2022-07-07 01:15:21,374] {logging_mixin.py:115} INFO - [2022-07-07 01:15:21,374] {dagbag.py:507} INFO - Filling up the DagBag from /opt/airflow/dags/projeto_api.py
[2022-07-07 01:15:21,415] {logging_mixin.py:115} INFO - [2022-07-07 01:15:21,412] {dagbag.py:320} ERROR - Failed to import: /opt/airflow/dags/projeto_api.py
Traceback (most recent call last):
  File "/home/airflow/.local/lib/python3.7/site-packages/urllib3/connection.py", line 175, in _new_conn
    (self._dns_host, self.port), self.timeout, **extra_kw
  File "/home/airflow/.local/lib/python3.7/site-packages/urllib3/util/connection.py", line 72, in create_connection
    for res in socket.getaddrinfo(host, port, family, socket.SOCK_STREAM):
  File "/usr/local/lib/python3.7/socket.py", line 752, in getaddrinfo
    for res in _socket.getaddrinfo(host, port, family, type, proto, flags):
socket.gaierror: [Errno -3] Temporary failure in name resolution

During handling of the above exception, another exception occurred:

Traceback (most recent call last):
  File "/home/airflow/.local/lib/python3.7/site-packages/urllib3/connectionpool.py", line 710, in urlopen
    chunked=chunked,
  File "/home/airflow/.local/lib/python3.7/site-packages/urllib3/connectionpool.py", line 386, in _make_request
    self._validate_conn(conn)
  File "/home/airflow/.local/lib/python3.7/site-packages/urllib3/connectionpool.py", line 1040, in _validate_conn
    conn.connect()
  File "/home/airflow/.local/lib/python3.7/site-packages/urllib3/connection.py", line 358, in connect
    self.sock = conn = self._new_conn()
  File "/home/airflow/.local/lib/python3.7/site-packages/urllib3/connection.py", line 187, in _new_conn
    self, "Failed to establish a new connection: %s" % e
urllib3.exceptions.NewConnectionError: <urllib3.connection.HTTPSConnection object at 0x7f3e6d2215d0>: Failed to establish a new connection: [Errno -3] Temporary failure in name resolution

During handling of the above exception, another exception occurred:

Traceback (most recent call last):
  File "/home/airflow/.local/lib/python3.7/site-packages/requests/adapters.py", line 450, in send
    timeout=timeout
  File "/home/airflow/.local/lib/python3.7/site-packages/urllib3/connectionpool.py", line 786, in urlopen
    method, url, error=e, _pool=self, _stacktrace=sys.exc_info()[2]
  File "/home/airflow/.local/lib/python3.7/site-packages/urllib3/util/retry.py", line 592, in increment
    raise MaxRetryError(_pool, url, error or ResponseError(cause))
urllib3.exceptions.MaxRetryError: HTTPSConnectionPool(host='www.mercadobitcoin.net', port=443): Max retries exceeded with url: /api/BTC/day-summary/2022/5/2/ (Caused by NewConnectionError('<urllib3.connection.HTTPSConnection object at 0x7f3e6d2215d0>: Failed to establish a new connection: [Errno -3] Temporary failure in name resolution'))

During handling of the above exception, another exception occurred:

Traceback (most recent call last):
  File "/home/airflow/.local/lib/python3.7/site-packages/airflow/models/dagbag.py", line 317, in parse
    loader.exec_module(new_module)
  File "<frozen importlib._bootstrap_external>", line 728, in exec_module
  File "<frozen importlib._bootstrap>", line 219, in _call_with_frames_removed
  File "/opt/airflow/dags/projeto_api.py", line 26, in <module>
    dia1 = Api_conn.get_api(2, 5, 2022)
  File "/opt/airflow/dags/projeto_api.py", line 19, in get_api
    response_API = requests.get(f'https://www.mercadobitcoin.net/api/BTC/day-summary/{year}/{month}/{day}/')
  File "/home/airflow/.local/lib/python3.7/site-packages/requests/api.py", line 75, in get
    return request('get', url, params=params, **kwargs)
  File "/home/airflow/.local/lib/python3.7/site-packages/requests/api.py", line 61, in request
    return session.request(method=method, url=url, **kwargs)
  File "/home/airflow/.local/lib/python3.7/site-packages/requests/sessions.py", line 529, in request
    resp = self.send(prep, **send_kwargs)
  File "/home/airflow/.local/lib/python3.7/site-packages/requests/sessions.py", line 645, in send
    r = adapter.send(request, **kwargs)
  File "/home/airflow/.local/lib/python3.7/site-packages/requests/adapters.py", line 519, in send
    raise ConnectionError(e, request=request)
requests.exceptions.ConnectionError: HTTPSConnectionPool(host='www.mercadobitcoin.net', port=443): Max retries exceeded with url: /api/BTC/day-summary/2022/5/2/ (Caused by NewConnectionError('<urllib3.connection.HTTPSConnection object at 0x7f3e6d2215d0>: Failed to establish a new connection: [Errno -3] Temporary failure in name resolution'))
[2022-07-07 01:15:21,415] {processor.py:653} WARNING - No viable dags retrieved from /opt/airflow/dags/projeto_api.py
[2022-07-07 01:15:21,456] {processor.py:161} INFO - Processing /opt/airflow/dags/projeto_api.py took 0.094 seconds
[2022-07-07 01:15:51,535] {processor.py:153} INFO - Started process (PID=530) to work on /opt/airflow/dags/projeto_api.py
[2022-07-07 01:15:51,563] {processor.py:641} INFO - Processing file /opt/airflow/dags/projeto_api.py for tasks to queue
[2022-07-07 01:15:51,565] {logging_mixin.py:115} INFO - [2022-07-07 01:15:51,564] {dagbag.py:507} INFO - Filling up the DagBag from /opt/airflow/dags/projeto_api.py
[2022-07-07 01:15:59,761] {logging_mixin.py:115} INFO - [2022-07-07 01:15:59,717] {dagbag.py:320} ERROR - Failed to import: /opt/airflow/dags/projeto_api.py
Traceback (most recent call last):
  File "/home/airflow/.local/lib/python3.7/site-packages/airflow/models/dagbag.py", line 317, in parse
    loader.exec_module(new_module)
  File "<frozen importlib._bootstrap_external>", line 728, in exec_module
  File "<frozen importlib._bootstrap>", line 219, in _call_with_frames_removed
  File "/opt/airflow/dags/projeto_api.py", line 27, in <module>
    load_json = Api_conn.load_data_json(dia1)
  File "/opt/airflow/dags/projeto_api.py", line 23, in load_data_json
    return json.loads(data)
  File "/usr/local/lib/python3.7/json/__init__.py", line 341, in loads
    raise TypeError(f'the JSON object must be str, bytes or bytearray, '
TypeError: the JSON object must be str, bytes or bytearray, not Response
[2022-07-07 01:15:59,762] {processor.py:653} WARNING - No viable dags retrieved from /opt/airflow/dags/projeto_api.py
[2022-07-07 01:15:59,837] {processor.py:161} INFO - Processing /opt/airflow/dags/projeto_api.py took 8.306 seconds
[2022-07-07 01:16:29,973] {processor.py:153} INFO - Started process (PID=558) to work on /opt/airflow/dags/projeto_api.py
[2022-07-07 01:16:30,026] {processor.py:641} INFO - Processing file /opt/airflow/dags/projeto_api.py for tasks to queue
[2022-07-07 01:16:30,027] {logging_mixin.py:115} INFO - [2022-07-07 01:16:30,027] {dagbag.py:507} INFO - Filling up the DagBag from /opt/airflow/dags/projeto_api.py
[2022-07-07 01:16:30,370] {logging_mixin.py:115} INFO - [2022-07-07 01:16:30,366] {dagbag.py:320} ERROR - Failed to import: /opt/airflow/dags/projeto_api.py
Traceback (most recent call last):
  File "/home/airflow/.local/lib/python3.7/site-packages/airflow/models/dagbag.py", line 317, in parse
    loader.exec_module(new_module)
  File "<frozen importlib._bootstrap_external>", line 728, in exec_module
  File "<frozen importlib._bootstrap>", line 219, in _call_with_frames_removed
  File "/opt/airflow/dags/projeto_api.py", line 27, in <module>
    load_json = Api_conn.load_data_json(dia1)
  File "/opt/airflow/dags/projeto_api.py", line 23, in load_data_json
    return json.loads(data)
  File "/usr/local/lib/python3.7/json/__init__.py", line 341, in loads
    raise TypeError(f'the JSON object must be str, bytes or bytearray, '
TypeError: the JSON object must be str, bytes or bytearray, not Response
[2022-07-07 01:16:30,370] {processor.py:653} WARNING - No viable dags retrieved from /opt/airflow/dags/projeto_api.py
[2022-07-07 01:16:30,445] {processor.py:161} INFO - Processing /opt/airflow/dags/projeto_api.py took 0.480 seconds
[2022-07-07 01:17:00,551] {processor.py:153} INFO - Started process (PID=577) to work on /opt/airflow/dags/projeto_api.py
[2022-07-07 01:17:00,552] {processor.py:641} INFO - Processing file /opt/airflow/dags/projeto_api.py for tasks to queue
[2022-07-07 01:17:00,554] {logging_mixin.py:115} INFO - [2022-07-07 01:17:00,554] {dagbag.py:507} INFO - Filling up the DagBag from /opt/airflow/dags/projeto_api.py
[2022-07-07 01:17:00,838] {logging_mixin.py:115} INFO - [2022-07-07 01:17:00,834] {dagbag.py:320} ERROR - Failed to import: /opt/airflow/dags/projeto_api.py
Traceback (most recent call last):
  File "/home/airflow/.local/lib/python3.7/site-packages/airflow/models/dagbag.py", line 317, in parse
    loader.exec_module(new_module)
  File "<frozen importlib._bootstrap_external>", line 728, in exec_module
  File "<frozen importlib._bootstrap>", line 219, in _call_with_frames_removed
  File "/opt/airflow/dags/projeto_api.py", line 27, in <module>
    load_json = Api_conn.load_data_json(dia1)
  File "/opt/airflow/dags/projeto_api.py", line 23, in load_data_json
    return json.loads(data)
  File "/usr/local/lib/python3.7/json/__init__.py", line 341, in loads
    raise TypeError(f'the JSON object must be str, bytes or bytearray, '
TypeError: the JSON object must be str, bytes or bytearray, not Response
[2022-07-07 01:17:00,839] {processor.py:653} WARNING - No viable dags retrieved from /opt/airflow/dags/projeto_api.py
[2022-07-07 01:17:00,922] {processor.py:161} INFO - Processing /opt/airflow/dags/projeto_api.py took 0.383 seconds
[2022-07-07 01:17:31,577] {processor.py:153} INFO - Started process (PID=607) to work on /opt/airflow/dags/projeto_api.py
[2022-07-07 01:17:31,940] {processor.py:641} INFO - Processing file /opt/airflow/dags/projeto_api.py for tasks to queue
[2022-07-07 01:17:31,957] {logging_mixin.py:115} INFO - [2022-07-07 01:17:31,957] {dagbag.py:507} INFO - Filling up the DagBag from /opt/airflow/dags/projeto_api.py
[2022-07-07 01:17:38,344] {logging_mixin.py:115} INFO - [2022-07-07 01:17:38,066] {dagbag.py:320} ERROR - Failed to import: /opt/airflow/dags/projeto_api.py
Traceback (most recent call last):
  File "/home/airflow/.local/lib/python3.7/site-packages/airflow/models/dagbag.py", line 317, in parse
    loader.exec_module(new_module)
  File "<frozen importlib._bootstrap_external>", line 728, in exec_module
  File "<frozen importlib._bootstrap>", line 219, in _call_with_frames_removed
  File "/opt/airflow/dags/projeto_api.py", line 27, in <module>
    load_json = Api_conn.load_data_json(dia1)
  File "/opt/airflow/dags/projeto_api.py", line 23, in load_data_json
    return json.loads(data)
  File "/usr/local/lib/python3.7/json/__init__.py", line 341, in loads
    raise TypeError(f'the JSON object must be str, bytes or bytearray, '
TypeError: the JSON object must be str, bytes or bytearray, not Response
[2022-07-07 01:17:38,430] {processor.py:653} WARNING - No viable dags retrieved from /opt/airflow/dags/projeto_api.py
[2022-07-07 01:17:38,648] {processor.py:161} INFO - Processing /opt/airflow/dags/projeto_api.py took 7.076 seconds
[2022-07-07 01:18:08,778] {processor.py:153} INFO - Started process (PID=627) to work on /opt/airflow/dags/projeto_api.py
[2022-07-07 01:18:08,840] {processor.py:641} INFO - Processing file /opt/airflow/dags/projeto_api.py for tasks to queue
[2022-07-07 01:18:10,445] {logging_mixin.py:115} INFO - [2022-07-07 01:18:10,445] {dagbag.py:507} INFO - Filling up the DagBag from /opt/airflow/dags/projeto_api.py
[2022-07-07 01:18:28,190] {logging_mixin.py:115} INFO - [2022-07-07 01:18:27,204] {dagbag.py:320} ERROR - Failed to import: /opt/airflow/dags/projeto_api.py
Traceback (most recent call last):
  File "/home/airflow/.local/lib/python3.7/site-packages/airflow/models/dagbag.py", line 317, in parse
    loader.exec_module(new_module)
  File "<frozen importlib._bootstrap_external>", line 728, in exec_module
  File "<frozen importlib._bootstrap>", line 219, in _call_with_frames_removed
  File "/opt/airflow/dags/projeto_api.py", line 27, in <module>
    load_json = Api_conn.load_data_json(dia1)
  File "/opt/airflow/dags/projeto_api.py", line 23, in load_data_json
    return json.loads(data)
  File "/usr/local/lib/python3.7/json/__init__.py", line 341, in loads
    raise TypeError(f'the JSON object must be str, bytes or bytearray, '
TypeError: the JSON object must be str, bytes or bytearray, not Response
[2022-07-07 01:18:28,284] {processor.py:653} WARNING - No viable dags retrieved from /opt/airflow/dags/projeto_api.py
[2022-07-07 01:18:29,088] {processor.py:161} INFO - Processing /opt/airflow/dags/projeto_api.py took 20.315 seconds
[2022-07-07 01:18:59,486] {processor.py:153} INFO - Started process (PID=663) to work on /opt/airflow/dags/projeto_api.py
[2022-07-07 01:18:59,496] {processor.py:641} INFO - Processing file /opt/airflow/dags/projeto_api.py for tasks to queue
[2022-07-07 01:18:59,498] {logging_mixin.py:115} INFO - [2022-07-07 01:18:59,498] {dagbag.py:507} INFO - Filling up the DagBag from /opt/airflow/dags/projeto_api.py
[2022-07-07 01:18:59,887] {logging_mixin.py:115} INFO - [2022-07-07 01:18:59,883] {dagbag.py:320} ERROR - Failed to import: /opt/airflow/dags/projeto_api.py
Traceback (most recent call last):
  File "/home/airflow/.local/lib/python3.7/site-packages/airflow/models/dagbag.py", line 317, in parse
    loader.exec_module(new_module)
  File "<frozen importlib._bootstrap_external>", line 728, in exec_module
  File "<frozen importlib._bootstrap>", line 219, in _call_with_frames_removed
  File "/opt/airflow/dags/projeto_api.py", line 27, in <module>
    load_json = Api_conn.load_data_json(dia1)
  File "/opt/airflow/dags/projeto_api.py", line 23, in load_data_json
    return json.loads(data)
  File "/usr/local/lib/python3.7/json/__init__.py", line 341, in loads
    raise TypeError(f'the JSON object must be str, bytes or bytearray, '
TypeError: the JSON object must be str, bytes or bytearray, not Response
[2022-07-07 01:18:59,888] {processor.py:653} WARNING - No viable dags retrieved from /opt/airflow/dags/projeto_api.py
[2022-07-07 01:18:59,945] {processor.py:161} INFO - Processing /opt/airflow/dags/projeto_api.py took 0.468 seconds
[2022-07-07 01:19:30,014] {processor.py:153} INFO - Started process (PID=690) to work on /opt/airflow/dags/projeto_api.py
[2022-07-07 01:19:30,015] {processor.py:641} INFO - Processing file /opt/airflow/dags/projeto_api.py for tasks to queue
[2022-07-07 01:19:30,020] {logging_mixin.py:115} INFO - [2022-07-07 01:19:30,016] {dagbag.py:507} INFO - Filling up the DagBag from /opt/airflow/dags/projeto_api.py
[2022-07-07 01:19:30,394] {logging_mixin.py:115} INFO - [2022-07-07 01:19:30,385] {dagbag.py:320} ERROR - Failed to import: /opt/airflow/dags/projeto_api.py
Traceback (most recent call last):
  File "/home/airflow/.local/lib/python3.7/site-packages/airflow/models/dagbag.py", line 317, in parse
    loader.exec_module(new_module)
  File "<frozen importlib._bootstrap_external>", line 728, in exec_module
  File "<frozen importlib._bootstrap>", line 219, in _call_with_frames_removed
  File "/opt/airflow/dags/projeto_api.py", line 27, in <module>
    load_json = Api_conn.load_data_json(dia1)
  File "/opt/airflow/dags/projeto_api.py", line 23, in load_data_json
    return json.loads(data)
  File "/usr/local/lib/python3.7/json/__init__.py", line 341, in loads
    raise TypeError(f'the JSON object must be str, bytes or bytearray, '
TypeError: the JSON object must be str, bytes or bytearray, not Response
[2022-07-07 01:19:30,395] {processor.py:653} WARNING - No viable dags retrieved from /opt/airflow/dags/projeto_api.py
[2022-07-07 01:19:30,442] {processor.py:161} INFO - Processing /opt/airflow/dags/projeto_api.py took 0.433 seconds
[2022-07-07 01:20:00,546] {processor.py:153} INFO - Started process (PID=710) to work on /opt/airflow/dags/projeto_api.py
[2022-07-07 01:20:00,596] {processor.py:641} INFO - Processing file /opt/airflow/dags/projeto_api.py for tasks to queue
[2022-07-07 01:20:00,626] {logging_mixin.py:115} INFO - [2022-07-07 01:20:00,626] {dagbag.py:507} INFO - Filling up the DagBag from /opt/airflow/dags/projeto_api.py
[2022-07-07 01:20:01,150] {logging_mixin.py:115} INFO - [2022-07-07 01:20:01,100] {dagbag.py:320} ERROR - Failed to import: /opt/airflow/dags/projeto_api.py
Traceback (most recent call last):
  File "/home/airflow/.local/lib/python3.7/site-packages/airflow/models/dagbag.py", line 317, in parse
    loader.exec_module(new_module)
  File "<frozen importlib._bootstrap_external>", line 728, in exec_module
  File "<frozen importlib._bootstrap>", line 219, in _call_with_frames_removed
  File "/opt/airflow/dags/projeto_api.py", line 27, in <module>
    load_json = Api_conn.load_data_json(dia1)
  File "/opt/airflow/dags/projeto_api.py", line 23, in load_data_json
    return json.loads(data)
  File "/usr/local/lib/python3.7/json/__init__.py", line 341, in loads
    raise TypeError(f'the JSON object must be str, bytes or bytearray, '
TypeError: the JSON object must be str, bytes or bytearray, not Response
[2022-07-07 01:20:01,150] {processor.py:653} WARNING - No viable dags retrieved from /opt/airflow/dags/projeto_api.py
[2022-07-07 01:20:01,254] {processor.py:161} INFO - Processing /opt/airflow/dags/projeto_api.py took 0.720 seconds
[2022-07-07 01:20:31,373] {processor.py:153} INFO - Started process (PID=729) to work on /opt/airflow/dags/projeto_api.py
[2022-07-07 01:20:31,374] {processor.py:641} INFO - Processing file /opt/airflow/dags/projeto_api.py for tasks to queue
[2022-07-07 01:20:31,375] {logging_mixin.py:115} INFO - [2022-07-07 01:20:31,375] {dagbag.py:507} INFO - Filling up the DagBag from /opt/airflow/dags/projeto_api.py
[2022-07-07 01:20:32,068] {logging_mixin.py:115} INFO - [2022-07-07 01:20:32,023] {dagbag.py:320} ERROR - Failed to import: /opt/airflow/dags/projeto_api.py
Traceback (most recent call last):
  File "/home/airflow/.local/lib/python3.7/site-packages/airflow/models/dagbag.py", line 317, in parse
    loader.exec_module(new_module)
  File "<frozen importlib._bootstrap_external>", line 728, in exec_module
  File "<frozen importlib._bootstrap>", line 219, in _call_with_frames_removed
  File "/opt/airflow/dags/projeto_api.py", line 27, in <module>
    load_json = Api_conn.load_data_json(dia1)
  File "/opt/airflow/dags/projeto_api.py", line 23, in load_data_json
    return json.loads(data)
  File "/usr/local/lib/python3.7/json/__init__.py", line 341, in loads
    raise TypeError(f'the JSON object must be str, bytes or bytearray, '
TypeError: the JSON object must be str, bytes or bytearray, not Response
[2022-07-07 01:20:32,068] {processor.py:653} WARNING - No viable dags retrieved from /opt/airflow/dags/projeto_api.py
[2022-07-07 01:20:32,258] {processor.py:161} INFO - Processing /opt/airflow/dags/projeto_api.py took 0.893 seconds
[2022-07-07 01:21:02,393] {processor.py:153} INFO - Started process (PID=757) to work on /opt/airflow/dags/projeto_api.py
[2022-07-07 01:21:02,445] {processor.py:641} INFO - Processing file /opt/airflow/dags/projeto_api.py for tasks to queue
[2022-07-07 01:21:02,445] {logging_mixin.py:115} INFO - [2022-07-07 01:21:02,445] {dagbag.py:507} INFO - Filling up the DagBag from /opt/airflow/dags/projeto_api.py
[2022-07-07 01:21:03,368] {logging_mixin.py:115} INFO - [2022-07-07 01:21:03,366] {dagbag.py:320} ERROR - Failed to import: /opt/airflow/dags/projeto_api.py
Traceback (most recent call last):
  File "/home/airflow/.local/lib/python3.7/site-packages/airflow/models/dagbag.py", line 317, in parse
    loader.exec_module(new_module)
  File "<frozen importlib._bootstrap_external>", line 728, in exec_module
  File "<frozen importlib._bootstrap>", line 219, in _call_with_frames_removed
  File "/opt/airflow/dags/projeto_api.py", line 27, in <module>
    load_json = Api_conn.load_data_json(dia1)
  File "/opt/airflow/dags/projeto_api.py", line 23, in load_data_json
    return json.loads(data)
  File "/usr/local/lib/python3.7/json/__init__.py", line 341, in loads
    raise TypeError(f'the JSON object must be str, bytes or bytearray, '
TypeError: the JSON object must be str, bytes or bytearray, not Response
[2022-07-07 01:21:03,369] {processor.py:653} WARNING - No viable dags retrieved from /opt/airflow/dags/projeto_api.py
[2022-07-07 01:21:03,422] {processor.py:161} INFO - Processing /opt/airflow/dags/projeto_api.py took 1.040 seconds
[2022-07-07 01:21:33,578] {processor.py:153} INFO - Started process (PID=775) to work on /opt/airflow/dags/projeto_api.py
[2022-07-07 01:21:33,579] {processor.py:641} INFO - Processing file /opt/airflow/dags/projeto_api.py for tasks to queue
[2022-07-07 01:21:33,581] {logging_mixin.py:115} INFO - [2022-07-07 01:21:33,580] {dagbag.py:507} INFO - Filling up the DagBag from /opt/airflow/dags/projeto_api.py
[2022-07-07 01:21:34,042] {logging_mixin.py:115} INFO - [2022-07-07 01:21:34,036] {dagbag.py:320} ERROR - Failed to import: /opt/airflow/dags/projeto_api.py
Traceback (most recent call last):
  File "/home/airflow/.local/lib/python3.7/site-packages/airflow/models/dagbag.py", line 317, in parse
    loader.exec_module(new_module)
  File "<frozen importlib._bootstrap_external>", line 728, in exec_module
  File "<frozen importlib._bootstrap>", line 219, in _call_with_frames_removed
  File "/opt/airflow/dags/projeto_api.py", line 27, in <module>
    load_json = Api_conn.load_data_json(dia1)
  File "/opt/airflow/dags/projeto_api.py", line 23, in load_data_json
    return json.loads(data)
  File "/usr/local/lib/python3.7/json/__init__.py", line 341, in loads
    raise TypeError(f'the JSON object must be str, bytes or bytearray, '
TypeError: the JSON object must be str, bytes or bytearray, not Response
[2022-07-07 01:21:34,043] {processor.py:653} WARNING - No viable dags retrieved from /opt/airflow/dags/projeto_api.py
[2022-07-07 01:21:34,128] {processor.py:161} INFO - Processing /opt/airflow/dags/projeto_api.py took 0.561 seconds
[2022-07-07 01:22:04,221] {processor.py:153} INFO - Started process (PID=794) to work on /opt/airflow/dags/projeto_api.py
[2022-07-07 01:22:04,221] {processor.py:641} INFO - Processing file /opt/airflow/dags/projeto_api.py for tasks to queue
[2022-07-07 01:22:04,222] {logging_mixin.py:115} INFO - [2022-07-07 01:22:04,222] {dagbag.py:507} INFO - Filling up the DagBag from /opt/airflow/dags/projeto_api.py
[2022-07-07 01:22:05,084] {logging_mixin.py:115} INFO - [2022-07-07 01:22:05,079] {dagbag.py:320} ERROR - Failed to import: /opt/airflow/dags/projeto_api.py
Traceback (most recent call last):
  File "/home/airflow/.local/lib/python3.7/site-packages/airflow/models/dagbag.py", line 317, in parse
    loader.exec_module(new_module)
  File "<frozen importlib._bootstrap_external>", line 728, in exec_module
  File "<frozen importlib._bootstrap>", line 219, in _call_with_frames_removed
  File "/opt/airflow/dags/projeto_api.py", line 27, in <module>
    load_json = Api_conn.load_data_json(dia1)
  File "/opt/airflow/dags/projeto_api.py", line 23, in load_data_json
    return json.loads(data)
  File "/usr/local/lib/python3.7/json/__init__.py", line 341, in loads
    raise TypeError(f'the JSON object must be str, bytes or bytearray, '
TypeError: the JSON object must be str, bytes or bytearray, not Response
[2022-07-07 01:22:05,085] {processor.py:653} WARNING - No viable dags retrieved from /opt/airflow/dags/projeto_api.py
[2022-07-07 01:22:05,158] {processor.py:161} INFO - Processing /opt/airflow/dags/projeto_api.py took 0.940 seconds
[2022-07-07 01:22:35,271] {processor.py:153} INFO - Started process (PID=823) to work on /opt/airflow/dags/projeto_api.py
[2022-07-07 01:22:35,273] {processor.py:641} INFO - Processing file /opt/airflow/dags/projeto_api.py for tasks to queue
[2022-07-07 01:22:35,274] {logging_mixin.py:115} INFO - [2022-07-07 01:22:35,274] {dagbag.py:507} INFO - Filling up the DagBag from /opt/airflow/dags/projeto_api.py
[2022-07-07 01:22:35,694] {logging_mixin.py:115} INFO - [2022-07-07 01:22:35,689] {dagbag.py:320} ERROR - Failed to import: /opt/airflow/dags/projeto_api.py
Traceback (most recent call last):
  File "/home/airflow/.local/lib/python3.7/site-packages/airflow/models/dagbag.py", line 317, in parse
    loader.exec_module(new_module)
  File "<frozen importlib._bootstrap_external>", line 728, in exec_module
  File "<frozen importlib._bootstrap>", line 219, in _call_with_frames_removed
  File "/opt/airflow/dags/projeto_api.py", line 27, in <module>
    load_json = Api_conn.load_data_json(dia1)
  File "/opt/airflow/dags/projeto_api.py", line 23, in load_data_json
    return json.loads(data)
  File "/usr/local/lib/python3.7/json/__init__.py", line 341, in loads
    raise TypeError(f'the JSON object must be str, bytes or bytearray, '
TypeError: the JSON object must be str, bytes or bytearray, not Response
[2022-07-07 01:22:35,695] {processor.py:653} WARNING - No viable dags retrieved from /opt/airflow/dags/projeto_api.py
[2022-07-07 01:22:35,755] {processor.py:161} INFO - Processing /opt/airflow/dags/projeto_api.py took 0.495 seconds
[2022-07-07 01:23:05,919] {processor.py:153} INFO - Started process (PID=843) to work on /opt/airflow/dags/projeto_api.py
[2022-07-07 01:23:05,928] {processor.py:641} INFO - Processing file /opt/airflow/dags/projeto_api.py for tasks to queue
[2022-07-07 01:23:05,929] {logging_mixin.py:115} INFO - [2022-07-07 01:23:05,929] {dagbag.py:507} INFO - Filling up the DagBag from /opt/airflow/dags/projeto_api.py
[2022-07-07 01:23:06,221] {logging_mixin.py:115} INFO - [2022-07-07 01:23:06,219] {dagbag.py:320} ERROR - Failed to import: /opt/airflow/dags/projeto_api.py
Traceback (most recent call last):
  File "/home/airflow/.local/lib/python3.7/site-packages/airflow/models/dagbag.py", line 317, in parse
    loader.exec_module(new_module)
  File "<frozen importlib._bootstrap_external>", line 728, in exec_module
  File "<frozen importlib._bootstrap>", line 219, in _call_with_frames_removed
  File "/opt/airflow/dags/projeto_api.py", line 27, in <module>
    load_json = Api_conn.load_data_json(dia1)
  File "/opt/airflow/dags/projeto_api.py", line 23, in load_data_json
    return json.loads(data)
  File "/usr/local/lib/python3.7/json/__init__.py", line 341, in loads
    raise TypeError(f'the JSON object must be str, bytes or bytearray, '
TypeError: the JSON object must be str, bytes or bytearray, not Response
[2022-07-07 01:23:06,221] {processor.py:653} WARNING - No viable dags retrieved from /opt/airflow/dags/projeto_api.py
[2022-07-07 01:23:06,264] {processor.py:161} INFO - Processing /opt/airflow/dags/projeto_api.py took 0.350 seconds
[2022-07-07 01:23:36,342] {processor.py:153} INFO - Started process (PID=870) to work on /opt/airflow/dags/projeto_api.py
[2022-07-07 01:23:36,342] {processor.py:641} INFO - Processing file /opt/airflow/dags/projeto_api.py for tasks to queue
[2022-07-07 01:23:36,343] {logging_mixin.py:115} INFO - [2022-07-07 01:23:36,343] {dagbag.py:507} INFO - Filling up the DagBag from /opt/airflow/dags/projeto_api.py
[2022-07-07 01:23:36,592] {logging_mixin.py:115} INFO - [2022-07-07 01:23:36,590] {dagbag.py:320} ERROR - Failed to import: /opt/airflow/dags/projeto_api.py
Traceback (most recent call last):
  File "/home/airflow/.local/lib/python3.7/site-packages/airflow/models/dagbag.py", line 317, in parse
    loader.exec_module(new_module)
  File "<frozen importlib._bootstrap_external>", line 728, in exec_module
  File "<frozen importlib._bootstrap>", line 219, in _call_with_frames_removed
  File "/opt/airflow/dags/projeto_api.py", line 27, in <module>
    load_json = Api_conn.load_data_json(dia1)
  File "/opt/airflow/dags/projeto_api.py", line 23, in load_data_json
    return json.loads(data)
  File "/usr/local/lib/python3.7/json/__init__.py", line 341, in loads
    raise TypeError(f'the JSON object must be str, bytes or bytearray, '
TypeError: the JSON object must be str, bytes or bytearray, not Response
[2022-07-07 01:23:36,592] {processor.py:653} WARNING - No viable dags retrieved from /opt/airflow/dags/projeto_api.py
[2022-07-07 01:23:36,668] {processor.py:161} INFO - Processing /opt/airflow/dags/projeto_api.py took 0.331 seconds
[2022-07-07 01:24:06,811] {processor.py:153} INFO - Started process (PID=889) to work on /opt/airflow/dags/projeto_api.py
[2022-07-07 01:24:06,825] {processor.py:641} INFO - Processing file /opt/airflow/dags/projeto_api.py for tasks to queue
[2022-07-07 01:24:06,827] {logging_mixin.py:115} INFO - [2022-07-07 01:24:06,827] {dagbag.py:507} INFO - Filling up the DagBag from /opt/airflow/dags/projeto_api.py
[2022-07-07 01:24:07,074] {logging_mixin.py:115} INFO - [2022-07-07 01:24:07,070] {dagbag.py:320} ERROR - Failed to import: /opt/airflow/dags/projeto_api.py
Traceback (most recent call last):
  File "/home/airflow/.local/lib/python3.7/site-packages/airflow/models/dagbag.py", line 317, in parse
    loader.exec_module(new_module)
  File "<frozen importlib._bootstrap_external>", line 728, in exec_module
  File "<frozen importlib._bootstrap>", line 219, in _call_with_frames_removed
  File "/opt/airflow/dags/projeto_api.py", line 27, in <module>
    load_json = Api_conn.load_data_json(dia1)
  File "/opt/airflow/dags/projeto_api.py", line 23, in load_data_json
    return json.loads(data)
  File "/usr/local/lib/python3.7/json/__init__.py", line 341, in loads
    raise TypeError(f'the JSON object must be str, bytes or bytearray, '
TypeError: the JSON object must be str, bytes or bytearray, not Response
[2022-07-07 01:24:07,075] {processor.py:653} WARNING - No viable dags retrieved from /opt/airflow/dags/projeto_api.py
[2022-07-07 01:24:07,193] {processor.py:161} INFO - Processing /opt/airflow/dags/projeto_api.py took 0.392 seconds
[2022-07-07 01:24:37,290] {processor.py:153} INFO - Started process (PID=908) to work on /opt/airflow/dags/projeto_api.py
[2022-07-07 01:24:37,314] {processor.py:641} INFO - Processing file /opt/airflow/dags/projeto_api.py for tasks to queue
[2022-07-07 01:24:37,316] {logging_mixin.py:115} INFO - [2022-07-07 01:24:37,315] {dagbag.py:507} INFO - Filling up the DagBag from /opt/airflow/dags/projeto_api.py
[2022-07-07 01:24:37,590] {logging_mixin.py:115} INFO - [2022-07-07 01:24:37,586] {dagbag.py:320} ERROR - Failed to import: /opt/airflow/dags/projeto_api.py
Traceback (most recent call last):
  File "/home/airflow/.local/lib/python3.7/site-packages/airflow/models/dagbag.py", line 317, in parse
    loader.exec_module(new_module)
  File "<frozen importlib._bootstrap_external>", line 728, in exec_module
  File "<frozen importlib._bootstrap>", line 219, in _call_with_frames_removed
  File "/opt/airflow/dags/projeto_api.py", line 27, in <module>
    load_json = Api_conn.load_data_json(dia1)
  File "/opt/airflow/dags/projeto_api.py", line 23, in load_data_json
    return json.loads(data)
  File "/usr/local/lib/python3.7/json/__init__.py", line 341, in loads
    raise TypeError(f'the JSON object must be str, bytes or bytearray, '
TypeError: the JSON object must be str, bytes or bytearray, not Response
[2022-07-07 01:24:37,591] {processor.py:653} WARNING - No viable dags retrieved from /opt/airflow/dags/projeto_api.py
[2022-07-07 01:24:37,658] {processor.py:161} INFO - Processing /opt/airflow/dags/projeto_api.py took 0.378 seconds
[2022-07-07 01:25:07,730] {processor.py:153} INFO - Started process (PID=935) to work on /opt/airflow/dags/projeto_api.py
[2022-07-07 01:25:07,777] {processor.py:641} INFO - Processing file /opt/airflow/dags/projeto_api.py for tasks to queue
[2022-07-07 01:25:07,779] {logging_mixin.py:115} INFO - [2022-07-07 01:25:07,778] {dagbag.py:507} INFO - Filling up the DagBag from /opt/airflow/dags/projeto_api.py
[2022-07-07 01:25:08,113] {logging_mixin.py:115} INFO - [2022-07-07 01:25:08,109] {dagbag.py:320} ERROR - Failed to import: /opt/airflow/dags/projeto_api.py
Traceback (most recent call last):
  File "/home/airflow/.local/lib/python3.7/site-packages/airflow/models/dagbag.py", line 317, in parse
    loader.exec_module(new_module)
  File "<frozen importlib._bootstrap_external>", line 728, in exec_module
  File "<frozen importlib._bootstrap>", line 219, in _call_with_frames_removed
  File "/opt/airflow/dags/projeto_api.py", line 27, in <module>
    load_json = Api_conn.load_data_json(dia1)
  File "/opt/airflow/dags/projeto_api.py", line 23, in load_data_json
    return json.loads(data)
  File "/usr/local/lib/python3.7/json/__init__.py", line 341, in loads
    raise TypeError(f'the JSON object must be str, bytes or bytearray, '
TypeError: the JSON object must be str, bytes or bytearray, not Response
[2022-07-07 01:25:08,146] {processor.py:653} WARNING - No viable dags retrieved from /opt/airflow/dags/projeto_api.py
[2022-07-07 01:25:08,315] {processor.py:161} INFO - Processing /opt/airflow/dags/projeto_api.py took 0.553 seconds
[2022-07-07 01:25:38,450] {processor.py:153} INFO - Started process (PID=954) to work on /opt/airflow/dags/projeto_api.py
[2022-07-07 01:25:38,450] {processor.py:641} INFO - Processing file /opt/airflow/dags/projeto_api.py for tasks to queue
[2022-07-07 01:25:38,451] {logging_mixin.py:115} INFO - [2022-07-07 01:25:38,451] {dagbag.py:507} INFO - Filling up the DagBag from /opt/airflow/dags/projeto_api.py
[2022-07-07 01:25:38,891] {logging_mixin.py:115} INFO - [2022-07-07 01:25:38,861] {dagbag.py:320} ERROR - Failed to import: /opt/airflow/dags/projeto_api.py
Traceback (most recent call last):
  File "/home/airflow/.local/lib/python3.7/site-packages/airflow/models/dagbag.py", line 317, in parse
    loader.exec_module(new_module)
  File "<frozen importlib._bootstrap_external>", line 728, in exec_module
  File "<frozen importlib._bootstrap>", line 219, in _call_with_frames_removed
  File "/opt/airflow/dags/projeto_api.py", line 27, in <module>
    load_json = Api_conn.load_data_json(dia1)
  File "/opt/airflow/dags/projeto_api.py", line 23, in load_data_json
    return json.loads(data)
  File "/usr/local/lib/python3.7/json/__init__.py", line 341, in loads
    raise TypeError(f'the JSON object must be str, bytes or bytearray, '
TypeError: the JSON object must be str, bytes or bytearray, not Response
[2022-07-07 01:25:38,892] {processor.py:653} WARNING - No viable dags retrieved from /opt/airflow/dags/projeto_api.py
[2022-07-07 01:25:38,977] {processor.py:161} INFO - Processing /opt/airflow/dags/projeto_api.py took 0.531 seconds
[2022-07-07 01:26:09,072] {processor.py:153} INFO - Started process (PID=982) to work on /opt/airflow/dags/projeto_api.py
[2022-07-07 01:26:09,105] {processor.py:641} INFO - Processing file /opt/airflow/dags/projeto_api.py for tasks to queue
[2022-07-07 01:26:09,107] {logging_mixin.py:115} INFO - [2022-07-07 01:26:09,106] {dagbag.py:507} INFO - Filling up the DagBag from /opt/airflow/dags/projeto_api.py
[2022-07-07 01:26:09,373] {logging_mixin.py:115} INFO - [2022-07-07 01:26:09,369] {dagbag.py:320} ERROR - Failed to import: /opt/airflow/dags/projeto_api.py
Traceback (most recent call last):
  File "/home/airflow/.local/lib/python3.7/site-packages/airflow/models/dagbag.py", line 317, in parse
    loader.exec_module(new_module)
  File "<frozen importlib._bootstrap_external>", line 728, in exec_module
  File "<frozen importlib._bootstrap>", line 219, in _call_with_frames_removed
  File "/opt/airflow/dags/projeto_api.py", line 27, in <module>
    load_json = Api_conn.load_data_json(dia1)
  File "/opt/airflow/dags/projeto_api.py", line 23, in load_data_json
    return json.loads(data)
  File "/usr/local/lib/python3.7/json/__init__.py", line 341, in loads
    raise TypeError(f'the JSON object must be str, bytes or bytearray, '
TypeError: the JSON object must be str, bytes or bytearray, not Response
[2022-07-07 01:26:09,374] {processor.py:653} WARNING - No viable dags retrieved from /opt/airflow/dags/projeto_api.py
[2022-07-07 01:26:09,464] {processor.py:161} INFO - Processing /opt/airflow/dags/projeto_api.py took 0.402 seconds
[2022-07-07 01:26:39,553] {processor.py:153} INFO - Started process (PID=1000) to work on /opt/airflow/dags/projeto_api.py
[2022-07-07 01:26:39,554] {processor.py:641} INFO - Processing file /opt/airflow/dags/projeto_api.py for tasks to queue
[2022-07-07 01:26:39,554] {logging_mixin.py:115} INFO - [2022-07-07 01:26:39,554] {dagbag.py:507} INFO - Filling up the DagBag from /opt/airflow/dags/projeto_api.py
[2022-07-07 01:26:39,792] {logging_mixin.py:115} INFO - [2022-07-07 01:26:39,790] {dagbag.py:320} ERROR - Failed to import: /opt/airflow/dags/projeto_api.py
Traceback (most recent call last):
  File "/home/airflow/.local/lib/python3.7/site-packages/airflow/models/dagbag.py", line 317, in parse
    loader.exec_module(new_module)
  File "<frozen importlib._bootstrap_external>", line 728, in exec_module
  File "<frozen importlib._bootstrap>", line 219, in _call_with_frames_removed
  File "/opt/airflow/dags/projeto_api.py", line 27, in <module>
    load_json = Api_conn.load_data_json(dia1)
  File "/opt/airflow/dags/projeto_api.py", line 23, in load_data_json
    return json.loads(data)
  File "/usr/local/lib/python3.7/json/__init__.py", line 341, in loads
    raise TypeError(f'the JSON object must be str, bytes or bytearray, '
TypeError: the JSON object must be str, bytes or bytearray, not Response
[2022-07-07 01:26:39,798] {processor.py:653} WARNING - No viable dags retrieved from /opt/airflow/dags/projeto_api.py
[2022-07-07 01:26:39,885] {processor.py:161} INFO - Processing /opt/airflow/dags/projeto_api.py took 0.335 seconds
[2022-07-07 01:27:09,963] {processor.py:153} INFO - Started process (PID=1027) to work on /opt/airflow/dags/projeto_api.py
[2022-07-07 01:27:10,011] {processor.py:641} INFO - Processing file /opt/airflow/dags/projeto_api.py for tasks to queue
[2022-07-07 01:27:10,012] {logging_mixin.py:115} INFO - [2022-07-07 01:27:10,012] {dagbag.py:507} INFO - Filling up the DagBag from /opt/airflow/dags/projeto_api.py
[2022-07-07 01:27:10,247] {logging_mixin.py:115} INFO - [2022-07-07 01:27:10,245] {dagbag.py:320} ERROR - Failed to import: /opt/airflow/dags/projeto_api.py
Traceback (most recent call last):
  File "/home/airflow/.local/lib/python3.7/site-packages/airflow/models/dagbag.py", line 317, in parse
    loader.exec_module(new_module)
  File "<frozen importlib._bootstrap_external>", line 728, in exec_module
  File "<frozen importlib._bootstrap>", line 219, in _call_with_frames_removed
  File "/opt/airflow/dags/projeto_api.py", line 27, in <module>
    load_json = Api_conn.load_data_json(dia1)
  File "/opt/airflow/dags/projeto_api.py", line 23, in load_data_json
    return json.loads(data)
  File "/usr/local/lib/python3.7/json/__init__.py", line 341, in loads
    raise TypeError(f'the JSON object must be str, bytes or bytearray, '
TypeError: the JSON object must be str, bytes or bytearray, not Response
[2022-07-07 01:27:10,248] {processor.py:653} WARNING - No viable dags retrieved from /opt/airflow/dags/projeto_api.py
[2022-07-07 01:27:10,349] {processor.py:161} INFO - Processing /opt/airflow/dags/projeto_api.py took 0.390 seconds
